Workbook
Name MARQUES: Achats!$C$15:$C$31
Name GENRE: Achats!$E$15:$E$31
Name ARTICLES: Achats!$B$15:$B$31
Name DATE_ACHAT: Achats!$F$15:$F$31
Name SKU: Achats!$G$15:$G$31

Sheet Achats
A1: ID | B1: ARTICLES | C1: MARQUE | D1: GENRE | E1: =IFERROR(__xludf.DUMMYFUNCTION("{""GENRE(data)""; MAP(D2:D31, LAMBDA(c, IF(c="""", """", IF(REGEXMATCH(c,""♀️ */ *♂️""),""Homme/ Femme"", IF(REGEXMATCH(c,""♀️ */ *Kevin""),""Femme/ Kevin"", IF(REGEXMATCH(c,""♂️ */ *Beno[îi]t""),""Homme/ Benoît"&""", IF(REGEXMATCH(c,""♀️""),""Femme"", IF(REGEXMATCH(c,""♂️""),""Homme"",""""))))) ) ) ) } "),"GENRE(data)") -> GENRE(data) | F1: DATE D'ACHAT | G1: =IFERROR(__xludf.DUMMYFUNCTION("{""REFERENCE""; MAP(B2:B31,C2:C31,E2:E31, LAMBDA(a,b,c, IF(a="""","""", TEXTJOIN("""",1, SUBSTITUTE(REGEXREPLACE("" ""&UPPER(TRIM(a)),""(^| )([A-ZÀ-ÖØ-öø-ÿ])[^ ]*"",""$2""),"" "",""""), SUBSTITUTE(REGEXREPLACE("" ""&UPPER(TRIM(b)"&"),""(^| )([A-ZÀ-ÖØ-öø-ÿ])[^ ]*"",""$2""),"" "",""""), SUBSTITUTE(REGEXREPLACE("" ""&UPPER(TRIM(c)),""(^| )([A-ZÀ-ÖØ-öø-ÿ])[^ ]*"",""$2""),"" "","""") ) & IFERROR(TEXT(d,""MMYY""),"""") ) ) )} "),"REFERENCE") -> REFERENCE | H1: GRADE | I1: FOURNISSEUR/CODE | J1: {={"MOIS"; IF(F15:F31="","", UPPER(TEXT(F15:F31,"mmmm")) )}} -> MOIS | K1: {={"MOIS NUM"; IF(F15:F31="", "", TEXT(MONTH(F15:F31),"00"))}} -> MOIS NUM | L1: DATE DE LIVRAISON | M1: {={"DELAI DE LIVRAISON";IF(L2:L31="","",L2:L31-F2:F31)}} -> DELAI DE LIVRAISON | N1: PRIX D'ACHAT SHIP INCLUS | O1: QUANTITÉ COMMANDÉE | P1: QUANTITÉ RECUE | Q1: {={"PRIX UNITAIRE BRUTE";IF(P2:P31="","",N2:N31/P2:P31)}} -> PRIX UNITAIRE BRUTE | R1: FRAIS DE LAVAGE | S1: TOTAL TTC | T1: {={"PRIX UNITAIRE TTC";IF(P2:P31="","",S2:S31/P2:P31)}} -> PRIX UNITAIRE TTC | U1: TRACKING | V1: PRÊT POUR MISE EN STOCK | DATE
A2: 99 | B2: SNEAKERS | C2: MIX | D2: ♀️ / ♂️ | E2: =IFERROR(__xludf.DUMMYFUNCTION("""COMPUTED_VALUE"""),"Homme/ Femme") -> Homme/ Femme | F2: 45889 | G2: =IFERROR(__xludf.DUMMYFUNCTION("""COMPUTED_VALUE"""),"SMHF") -> SMHF | H2: A | I2: WHAT NOT/VINTED | J2: FÉVRIER | K2: 02 | L2: 45898 | M2: 9 | N2: 35 | O2: 1 | P2: 1 | Q2: 35 | R2: 0 | S2: =SUM(Q2*P2+R2) -> 35 | T2: 35 | V2: 45899
A3: 98 | B3: SNEAKERS | C3: MIX | D3: ♀️ / ♂️ | E3: =IFERROR(__xludf.DUMMYFUNCTION("""COMPUTED_VALUE"""),"Homme/ Femme") -> Homme/ Femme | F3: 45889 | G3: =IFERROR(__xludf.DUMMYFUNCTION("""COMPUTED_VALUE"""),"SMHF") -> SMHF | H3: A | I3: WHAT NOT/VINTED | J3: AOÛT | K3: 08 | L3: 45898 | M3: 9 | N3: 75 | O3: 1 | P3: 1 | Q3: 75 | R3: 0 | S3: =SUM(Q3*P3+R3) -> 75 | T3: 75 | V3: 45899
A4: 97 | B4: SNEAKERS | C4: MIX | D4: ♀️ / ♂️ | E4: =IFERROR(__xludf.DUMMYFUNCTION("""COMPUTED_VALUE"""),"Homme/ Femme") -> Homme/ Femme | F4: 45877 | G4: =IFERROR(__xludf.DUMMYFUNCTION("""COMPUTED_VALUE"""),"SMHF") -> SMHF | H4: A | I4: WHAT NOT/VINTED | J4: AOÛT | K4: 08 | L4: 45886 | M4: 9 | N4: 41.24 | O4: 1 | P4: 1 | Q4: 41.24 | R4: 0 | S4: =SUM(Q4*P4+R4) -> 41.24 | T4: 41.24 | V4: 45887
A5: 96 | B5: SNEAKERS | C5: MIX | D5: ♀️ / ♂️ | E5: =IFERROR(__xludf.DUMMYFUNCTION("""COMPUTED_VALUE"""),"Homme/ Femme") -> Homme/ Femme | F5: 45877 | G5: =IFERROR(__xludf.DUMMYFUNCTION("""COMPUTED_VALUE"""),"SMHF") -> SMHF | H5: A | I5: WHAT NOT/VINTED | J5: SEPTEMBRE | K5: 09 | L5: 45886 | M5: 9 | N5: 28.61 | O5: 1 | P5: 1 | Q5: 28.61 | R5: 0 | S5: =SUM(Q5*P5+R5) -> 28.61 | T5: 28.61 | V5: 45887
A6: 95 | B6: SNEAKERS | C6: MIX | D6: ♀️ / ♂️ | E6: =IFERROR(__xludf.DUMMYFUNCTION("""COMPUTED_VALUE"""),"Homme/ Femme") -> Homme/ Femme | F6: 45892 | G6: =IFERROR(__xludf.DUMMYFUNCTION("""COMPUTED_VALUE"""),"SMHF") -> SMHF | H6: A | I6: WHAT NOT/VINTED | J6: SEPTEMBRE | K6: 09 | L6: 45901 | M6: 9 | N6: 9.39 | O6: 1 | P6: 1 | Q6: 9.39 | R6: 0 | S6: =SUM(Q6*P6+R6) -> 9.39 | T6: 9.39 | V6: 45902
A7: 94 | B7: SNEAKERS | C7: MIX | D7: ♀️ / ♂️ | E7: =IFERROR(__xludf.DUMMYFUNCTION("""COMPUTED_VALUE"""),"Homme/ Femme") -> Homme/ Femme | F7: 45877 | G7: =IFERROR(__xludf.DUMMYFUNCTION("""COMPUTED_VALUE"""),"SMHF") -> SMHF | H7: A | I7: WHAT NOT/VINTED | J7: SEPTEMBRE | K7: 09 | L7: 45886 | M7: 9 | N7: 60.61 | O7: 1 | P7: 1 | Q7: 60.61 | R7: 0 | S7: =SUM(Q7*P7+R7) -> 60.61 | T7: 60.61 | V7: 45887
A8: 93 | B8: SNEAKERS | C8: MIX | D8: ♀️ / ♂️ | E8: =IFERROR(__xludf.DUMMYFUNCTION("""COMPUTED_VALUE"""),"Homme/ Femme") -> Homme/ Femme | F8: 45877 | G8: =IFERROR(__xludf.DUMMYFUNCTION("""COMPUTED_VALUE"""),"SMHF") -> SMHF | H8: A | I8: WHAT NOT/VINTED | J8: SEPTEMBRE | K8: 09 | L8: 45886 | M8: 9 | N8: 78.75 | O8: 1 | P8: 1 | Q8: 78.75 | R8: 0 | S8: =SUM(Q8*P8+R8) -> 78.75 | T8: 78.75 | V8: 45887
A9: 92 | B9: SNEAKERS | C9: MIX | D9: ♀️ / ♂️ | E9: =IFERROR(__xludf.DUMMYFUNCTION("""COMPUTED_VALUE"""),"Homme/ Femme") -> Homme/ Femme | F9: 45877 | G9: =IFERROR(__xludf.DUMMYFUNCTION("""COMPUTED_VALUE"""),"SMHF") -> SMHF | H9: A | I9: WHAT NOT/VINTED | J9: SEPTEMBRE | K9: 09 | L9: 45886 | M9: 9 | N9: 83.54 | O9: 1 | P9: 1 | Q9: 83.54 | R9: 0 | S9: =SUM(Q9*P9+R9) -> 83.54 | T9: 83.54 | V9: 45887
A10: 91 | B10: SNEAKERS | C10: MIX | D10: ♀️ / ♂️ | E10: =IFERROR(__xludf.DUMMYFUNCTION("""COMPUTED_VALUE"""),"Homme/ Femme") -> Homme/ Femme | F10: 45889 | G10: =IFERROR(__xludf.DUMMYFUNCTION("""COMPUTED_VALUE"""),"SMHF") -> SMHF | H10: A | I10: WHAT NOT/VINTED | J10: SEPTEMBRE | K10: 09 | L10: 45898 | M10: 9 | N10: 190 | O10: 1 | P10: 1 | Q10: 190 | R10: 0 | S10: =SUM(Q10*P10+R10) -> 190 | T10: 190 | V10: 45899
A11: 90 | B11: SNEAKERS | C11: MIX | D11: ♀️ / ♂️ | E11: =IFERROR(__xludf.DUMMYFUNCTION("""COMPUTED_VALUE"""),"Homme/ Femme") -> Homme/ Femme | F11: 45877 | G11: =IFERROR(__xludf.DUMMYFUNCTION("""COMPUTED_VALUE"""),"SMHF") -> SMHF | H11: A | I11: WHAT NOT/VINTED | J11: OCTOBRE | K11: 10 | L11: 45886 | M11: 9 | N11: 43.54 | O11: 1 | P11: 1 | Q11: 43.54 | R11: 0 | S11: =SUM(Q11*P11+R11) -> 43.54 | T11: 43.54 | V11: 45887
A12: 89 | B12: SNEAKERS | C12: MIX | D12: ♀️ / ♂️ | E12: =IFERROR(__xludf.DUMMYFUNCTION("""COMPUTED_VALUE"""),"Homme/ Femme") -> Homme/ Femme | F12: 45892 | G12: =IFERROR(__xludf.DUMMYFUNCTION("""COMPUTED_VALUE"""),"SMHF") -> SMHF | H12: A | I12: WHAT NOT/VINTED | J12: OCTOBRE | K12: 10 | L12: 45901 | M12: 9 | N12: 11.19 | O12: 1 | P12: 1 | Q12: 11.19 | R12: 0 | S12: =SUM(Q12*P12+R12) -> 11.19 | T12: 11.19 | V12: 45902
A13: 88 | B13: SNEAKERS | C13: MIX | D13: ♀️ / ♂️ | E13: =IFERROR(__xludf.DUMMYFUNCTION("""COMPUTED_VALUE"""),"Homme/ Femme") -> Homme/ Femme | F13: 45877 | G13: =IFERROR(__xludf.DUMMYFUNCTION("""COMPUTED_VALUE"""),"SMHF") -> SMHF | H13: A | I13: WHAT NOT/VINTED | J13: OCTOBRE | K13: 10 | L13: 45886 | M13: 9 | N13: 38.18 | O13: 1 | P13: 1 | Q13: 38.18 | R13: 0 | S13: =SUM(Q13*P13+R13) -> 38.18 | T13: 38.18 | V13: 45887
A14: 2 | B14: VÊTEMENTS | C14: MIX WHAT NOT | D14: ♀️ / ♂️ | E14: =IFERROR(__xludf.DUMMYFUNCTION("""COMPUTED_VALUE"""),"Homme/ Femme") -> Homme/ Femme | F14: 45887 | G14: =IFERROR(__xludf.DUMMYFUNCTION("""COMPUTED_VALUE"""),"VMWNHF") -> VMWNHF | H14: A | I14: WHAT NOT | J14: OCTOBRE | K14: 10 | L14: 45898 | M14: 11 | N14: 38.83 | O14: 7 | P14: 7 | Q14: 5.5471429 | R14: 0 | S14: =SUM(Q14*P14+R14) -> 38.83 | T14: 5.5471429 | V14: 45899
A15: 3 | B15: VÊTEMENTS | C15: PERSO | D15: ♂️/ Benoît | E15: =IFERROR(__xludf.DUMMYFUNCTION("""COMPUTED_VALUE"""),"Homme/ Benoît") -> Homme/ Benoît | F15: 43890 | G15: =IFERROR(__xludf.DUMMYFUNCTION("""COMPUTED_VALUE"""),"VPHB") -> VPHB | H15: A | I15: BENOIT STAMBACH | J15: OCTOBRE | K15: 10 | L15: 43891 | M15: 1 | N15: 0 | O15: 17 | P15: 17 | Q15: 0 | R15: 0 | S15: =SUM(Q15*P15+R15) -> 0 | T15: 0 | V15: 45809
A16: 4 | B16: JEANS | C16: LEVIS | D16: ♀️/ Kevin | E16: =IFERROR(__xludf.DUMMYFUNCTION("""COMPUTED_VALUE"""),"Femme/ Kevin") -> Femme/ Kevin | F16: 45898 | G16: =IFERROR(__xludf.DUMMYFUNCTION("""COMPUTED_VALUE"""),"JLFK") -> JLFK | H16: A | I16: SUPPLY GDD EXPORT/ 1 | L16: 45904 | M16: 6 | N16: 408 | O16: 60 | P16: 62 | Q16: 6.5806452 | R16: 30.5 | S16: 438.94 | T16: 7.0796774 | V16: 45905
A17: 5 | B17: VÊTEMENTS | C17: TYMAN | D17: ♀️ / ♂️ | E17: =IFERROR(__xludf.DUMMYFUNCTION("""COMPUTED_VALUE"""),"Homme/ Femme") -> Homme/ Femme | F17: 45899 | G17: =IFERROR(__xludf.DUMMYFUNCTION("""COMPUTED_VALUE"""),"VTHF") -> VTHF | H17: A | I17: TYMAN | L17: 45906 | M17: 7 | N17: 120.04 | O17: 84 | P17: 84 | Q17: 1.4290476 | R17: 0 | S17: 120.15 | T17: 1.4303571 | V17: 45907
A18: 6 | B18: JACKET | C18: MIX | D18: ♀️ / ♂️ | E18: =IFERROR(__xludf.DUMMYFUNCTION("""COMPUTED_VALUE"""),"Homme/ Femme") -> Homme/ Femme | F18: 45910 | G18: =IFERROR(__xludf.DUMMYFUNCTION("""COMPUTED_VALUE"""),"JMHF") -> JMHF | H18: B | I18: SUPPLY GDD EXPORT/ 1 | L18: 45922 | M18: 12 | N18: 238 | O18: 60 | P18: 60 | Q18: 3.9666667 | R18: 47 | S18: 285.33 | T18: 4.7555 | V18: 45923
A19: 7 | B19: POLAIRE | C19: THE NORTH FACE | D19: ♀️ | E19: =IFERROR(__xludf.DUMMYFUNCTION("""COMPUTED_VALUE"""),"Femme") -> Femme | F19: 45923 | G19: =IFERROR(__xludf.DUMMYFUNCTION("""COMPUTED_VALUE"""),"PTNFF") -> PTNFF | H19: A | I19: SUPPLY / 105 | L19: 45952 | M19: 29 | N19: 184 | O19: 20 | P19: 20 | Q19: 9.2 | R19: 15.33 | S19: =SUM(Q19*P19+R19) -> 199.33 | T19: 9.9665 | U19: 3652902223 DHL | V19: 45953
A20: 8 | B20: POLAIRE | C20: COLUMBIA | D20: ♀️ | E20: =IFERROR(__xludf.DUMMYFUNCTION("""COMPUTED_VALUE"""),"Femme") -> Femme | F20: 45923 | G20: =IFERROR(__xludf.DUMMYFUNCTION("""COMPUTED_VALUE"""),"PCF") -> PCF | H20: A | I20: SUPPLY / 105 | L20: 45952 | M20: 29 | N20: 65 | O20: 10 | P20: 10 | Q20: 6.5 | R20: 7.66 | S20: =SUM(Q20*P20+R20) -> 72.66 | T20: 7.266 | U20: 3652902223 DHL | V20: 45953
A21: 9 | B21: JEANS | C21: LEVIS | D21: ♀️ | E21: =IFERROR(__xludf.DUMMYFUNCTION("""COMPUTED_VALUE"""),"Femme") -> Femme | F21: 45925 | G21: =IFERROR(__xludf.DUMMYFUNCTION("""COMPUTED_VALUE"""),"JLF") -> JLF | H21: A | I21: GDD EXPORT / 1 | L21: 45937 | M21: 12 | N21: 408 | O21: 60 | P21: 64 | Q21: 6.375 | R21: 45.45 | S21: 453.56 | T21: 7.086875 | V21: 45938
A22: 10 | B22: POLAIRE | C22: THE NORTH FACE | D22: ♀️ | E22: =IFERROR(__xludf.DUMMYFUNCTION("""COMPUTED_VALUE"""),"Femme") -> Femme | F22: 45925 | G22: =IFERROR(__xludf.DUMMYFUNCTION("""COMPUTED_VALUE"""),"PTNFF") -> PTNFF | H22: A | I22: GDD EXPORT / 1 | L22: 45937 | M22: 12 | N22: 436 | O22: 40 | P22: 41 | Q22: 10.634146 | R22: 30.05 | S22: =SUM(Q22*P22+R22) -> 466.05 | T22: 11.367073 | V22: 45938
A23: 11 | B23: JEANS | C23: LEVIS | D23: ♀️ | E23: =IFERROR(__xludf.DUMMYFUNCTION("""COMPUTED_VALUE"""),"Femme") -> Femme | F23: 45928 | G23: =IFERROR(__xludf.DUMMYFUNCTION("""COMPUTED_VALUE"""),"JLF") -> JLF | H23: A | I23: SUPPLY GDD EXPORT / 1 | L23: 45937 | M23: 9 | N23: 464 | O23: 70 | P23: 73 | Q23: 6.3561644 | R23: 52.78 | S23: =SUM(Q23*P23+R23) -> 516.78 | T23: 7.0791781 | V23: 45938
A24: 12 | B24: JACKET | C24: CARHARTT REWORK | D24: ♀️ | E24: =IFERROR(__xludf.DUMMYFUNCTION("""COMPUTED_VALUE"""),"Femme") -> Femme | F24: 45934 | G24: =IFERROR(__xludf.DUMMYFUNCTION("""COMPUTED_VALUE"""),"JCRF") -> JCRF | H24: A | I24: SUPPLY CODE 103 | N24: 525 | O24: 30 | S24: =SUM(Q24*P24+R24) -> 0 | V24: FALSE
A25: 13 | B25: PULL | C25: TOMMY HILFIGER | D25: ♀️ | E25: =IFERROR(__xludf.DUMMYFUNCTION("""COMPUTED_VALUE"""),"Femme") -> Femme | F25: 45939 | G25: =IFERROR(__xludf.DUMMYFUNCTION("""COMPUTED_VALUE"""),"PTHF") -> PTHF | H25: A | I25: SUPPLY CODE 3 | L25: 45944 | M25: 5 | N25: 200 | O25: 55 | P25: 56 | Q25: 3.5714286 | R25: 26 | S25: =SUM(Q25*P25+R25) -> 226 | T25: 4.0357143 | V25: 45945
A26: 14 | B26: JEANS | C26: LEVIS | D26: ♀️ | E26: =IFERROR(__xludf.DUMMYFUNCTION("""COMPUTED_VALUE"""),"Femme") -> Femme | F26: 45941 | G26: =IFERROR(__xludf.DUMMYFUNCTION("""COMPUTED_VALUE"""),"JLF") -> JLF | H26: A | I26: SUPPLY GDD 1 | L26: 45947 | M26: 6 | N26: 654 | O26: 100 | P26: 100 | Q26: 6.54 | R26: 55 | S26: =SUM(Q26*P26+R26) -> 709 | T26: 7.09 | V26: 45948
A27: 15 | B27: JEANS | C27: LEVIS | D27: ♀️ | E27: =IFERROR(__xludf.DUMMYFUNCTION("""COMPUTED_VALUE"""),"Femme") -> Femme | F27: 45953 | G27: =IFERROR(__xludf.DUMMYFUNCTION("""COMPUTED_VALUE"""),"JLF") -> JLF | H27: A | I27: SUPPLY GDD 1 | L27: 45959 | M27: 6 | N27: 634 | O27: 100 | P27: 100 | Q27: 6.34 | R27: 80.5 | S27: =SUM(Q27*P27+R27) -> 714.5 | T27: 7.145 | V27: 45960
A28: 16 | B28: PULL | C28: TOMMY HILFIGER | D28: ♀️ | E28: =IFERROR(__xludf.DUMMYFUNCTION("""COMPUTED_VALUE"""),"Femme") -> Femme | F28: 45960 | G28: =IFERROR(__xludf.DUMMYFUNCTION("""COMPUTED_VALUE"""),"PTHF") -> PTHF | H28: A | I28: SUPPLY CODE 3 | O28: 200 | S28: =SUM(Q28*P28+R28) -> 0 | V28: FALSE
E29: =IFERROR(__xludf.DUMMYFUNCTION("""COMPUTED_VALUE"""),"") | G29: =IFERROR(__xludf.DUMMYFUNCTION("""COMPUTED_VALUE"""),"") | V29: FALSE
E30: =IFERROR(__xludf.DUMMYFUNCTION("""COMPUTED_VALUE"""),"") | G30: =IFERROR(__xludf.DUMMYFUNCTION("""COMPUTED_VALUE"""),"") | V30: FALSE
E31: =IFERROR(__xludf.DUMMYFUNCTION("""COMPUTED_VALUE"""),"") | G31: =IFERROR(__xludf.DUMMYFUNCTION("""COMPUTED_VALUE"""),"") | V31: FALSE

Sheet Stock
A1: ID | B1: ARTICLES | C1: SKU(ancienne nomenclature) | D1: SKU | E1: DATE DE LIVRAISON | F1: DATE DE MISE EN STOCK | G1: MIS EN LIGNE | DATE DE MISE EN LIGNE | H1: PUBLIÉ | DATE DE PUBLICATION | I1: VENDU | DATE DE VENTE | J1: PRIX DE VENTE | K1: TAILLE | L1: LOTS | M1: VALIDER
A2: 3 | B2: VÊTEMENTS PERSO Homme/ Benoît | D2: VPHB-1 | E2: 43891 | F2: 45809 | G2: 45810 | H2: 45811
A3: 3 | B3: VÊTEMENTS PERSO Homme/ Benoît | D3: VPHB-2 | E3: 43891 | F3: 45809 | G3: 45810 | H3: 45811
A4: 3 | B4: VÊTEMENTS PERSO Homme/ Benoît | D4: VPHB-3 | E4: 43891 | F4: 45809 | G4: 45810 | H4: 45811
A5: 3 | B5: VÊTEMENTS PERSO Homme/ Benoît | D5: VPHB-4 | E5: 43891 | F5: 45809 | G5: 45810 | H5: 45811
A6: 3 | B6: VÊTEMENTS PERSO Homme/ Benoît | D6: VPHB-5 | E6: 43891 | F6: 45809 | G6: 45810 | H6: 45811
A7: 3 | B7: VÊTEMENTS PERSO Homme/ Benoît | D7: VPHB-6 | E7: 43891 | F7: 45809 | G7: 45810 | H7: 45811
A8: 3 | B8: VÊTEMENTS PERSO Homme/ Benoît | D8: VPHB-7 | E8: 43891 | F8: 45809 | G8: 45810 | H8: 45811
A9: 3 | B9: VÊTEMENTS PERSO Homme/ Benoît | D9: VPHB-8 | E9: 43891 | F9: 45809 | G9: 45810 | H9: 45811
A10: 3 | B10: VÊTEMENTS PERSO Homme/ Benoît | D10: VPHB-9 | E10: 43891 | F10: 45809 | G10: 45810 | H10: 45811
A11: 3 | B11: VÊTEMENTS PERSO Homme/ Benoît | D11: VPHB-10 | E11: 43891 | F11: 45809 | G11: 45810 | H11: 45811
A12: 3 | B12: VÊTEMENTS PERSO Homme/ Benoît | D12: VPHB-11 | E12: 43891 | F12: 45809 | G12: 45810 | H12: 45811
A13: 3 | B13: VÊTEMENTS PERSO Homme/ Benoît | D13: VPHB-12 | E13: 43891 | F13: 45809 | G13: 45810 | H13: 45811
... A16: 3 | B16: VÊTEMENTS PERSO Homme/ Benoît | D16: VPHB-16 | E16: 43891 | F16: 45809 | G16: 45810 | H16: 45811
A17: 4 | B17: JEANS LEVIS Femme/ Kevin | C17: JLFK-21 | D17: JLFK-21 | E17: 45904 | F17: 45905 | G17: 45906 | H17: 45907
A18: 4 | B18: JEANS LEVIS Femme/ Kevin | C18: JLFK-27 | D18: JLFK-27 | E18: 45904 | F18: 45905 | G18: 45906 | H18: 45907
A19: 4 | B19: JEANS LEVIS Femme/ Kevin | C19: JLFK-31 | D19: JLFK-31 | E19: 45904 | F19: 45905 | G19: 45906 | H19: 45907
A20: 4 | B20: JEANS LEVIS Femme/ Kevin | C20: JLFK-32 | D20: JLFK-32 | E20: 45904 | F20: 45905 | G20: 45906 | H20: 45907
A21: 4 | B21: JEANS LEVIS Femme/ Kevin | C21: JLFK-33 | D21: JLFK-33 | E21: 45904 | F21: 45905 | G21: 45906 | H21: 45907
A22: 4 | B22: JEANS LEVIS Femme/ Kevin | C22: JLFK-37 | D22: JLFK-37 | E22: 45904 | F22: 45905 | G22: 45906 | H22: 45907
A23: 4 | B23: JEANS LEVIS Femme/ Kevin | C23: JLFK-44 | D23: JLFK-44 | E23: 45904 | F23: 45905 | G23: 45906 | H23: 45907
A24: 4 | B24: JEANS LEVIS Femme/ Kevin | C24: JLFK-46 | D24: JLFK-46 | E24: 45904 | F24: 45905 | G24: 45906 | H24: 45907
A25: 4 | B25: JEANS LEVIS Femme/ Kevin | C25: JLFK-55 | D25: JLFK-55 | E25: 45904 | F25: 45905 | G25: 45906 | H25: 45907
A26: 4 | B26: JEANS LEVIS Femme/ Kevin | C26: JLFK-60 | D26: JLFK-60 | E26: 45904 | F26: 45905 | G26: 45906 | H26: 45907
A27: 4 | B27: JEANS LEVIS Femme/ Kevin | C27: JLFK-65 | D27: JLFK-65 | E27: 45904 | F27: 45905 | G27: 45907 | H27: 45908
A28: 4 | B28: JEANS LEVIS Femme/ Kevin | C28: JLFK-69 | D28: JLFK-69 | E28: 45904 | F28: 45905 | G28: 45907 | H28: 45908
... A33: 4 | B33: JEANS LEVIS Femme/ Kevin | C33: JLFK-82 | D33: JLFK-82 | E33: 45904 | F33: 45905 | G33: 45907 | H33: 45908
A34: 5 | B34: VÊTEMENTS TYMAN Homme/ Femme | D34: VTHF-17 | E34: 45906 | F34: 45907 | G34: 45908 | H34: 45909
A35: 5 | B35: VÊTEMENTS TYMAN Homme/ Femme | D35: VTHF-18 | E35: 45906 | F35: 45907 | G35: 45908 | H35: 45909
A36: 5 | B36: VÊTEMENTS TYMAN Homme/ Femme | D36: VTHF-19 | E36: 45906 | F36: 45907 | G36: 45908 | H36: 45909
A37: 5 | B37: VÊTEMENTS TYMAN Homme/ Femme | D37: VTHF-20 | E37: 45906 | F37: 45907 | G37: 45908 | H37: 45909
A38: 5 | B38: VÊTEMENTS TYMAN Homme/ Femme | D38: VTHF-21 | E38: 45906 | F38: 45907 | G38: 45908 | H38: 45909
A39: 5 | B39: VÊTEMENTS TYMAN Homme/ Femme | D39: VTHF-22 | E39: 45906 | F39: 45907 | G39: 45908 | H39: 45909
A40: 5 | B40: VÊTEMENTS TYMAN Homme/ Femme | D40: VTHF-23 | E40: 45906 | F40: 45907 | G40: 45908 | H40: 45909
A41: 5 | B41: VÊTEMENTS TYMAN Homme/ Femme | D41: VTHF-24 | E41: 45906 | F41: 45907 | G41: 45908 | H41: 45909
A42: 5 | B42: VÊTEMENTS TYMAN Homme/ Femme | D42: VTHF-25 | E42: 45906 | F42: 45907 | G42: 45908 | H42: 45909
A43: 5 | B43: VÊTEMENTS TYMAN Homme/ Femme | D43: VTHF-26 | E43: 45906 | F43: 45907 | G43: 45908 | H43: 45909
A44: 5 | B44: VÊTEMENTS TYMAN Homme/ Femme | D44: VTHF-27 | E44: 45906 | F44: 45907 | G44: 45909 | H44: 45910
A45: 5 | B45: VÊTEMENTS TYMAN Homme/ Femme | D45: VTHF-28 | E45: 45906 | F45: 45907 | G45: 45909 | H45: 45910
... A64: 5 | B64: VÊTEMENTS TYMAN Homme/ Femme | D64: VTHF-47 | E64: 45906 | F64: 45907 | G64: 45910 | H64: 45911
...

Sheet Suivi stockvaleurs
A1: Références | B1: Quantité | C1: Valeurs | D1: Valorisation de toutes les REF | E1: SKU's
A2: PTHF | B2: =IF($A2="","","En stock : "& IF($A2="TOUTES", COUNTIF(Stock!$D:$D,"*-*"), COUNTIF(Stock!$D:$D,$A2&"-*") )& " pièces") -> En stock : 30 pièces | C2: =IF($A2="","",IF( $A2="TOUTES", SUMPRODUCT( (Stock!$D$2:$D1000<>"") * IFERROR(VLOOKUP(Stock!$A$2:$A1000,Achats!$A$2:$T1000,20,FALSE),0) ), COUNTIF(Stock!$D:$D,$A2&"-*") * IFERROR(VLOOKUP($A2,Achats!$G:$T,14,FALSE),0) )) -> 121.07143 | D2: =C2*2 -> 242.14286 | E2: =IFERROR(__xludf.DUMMYFUNCTION("SORT( UNIQUE( FILTER( Achats!$G$2:$G1000, Achats!$G$2:$G1000<>"""" ) ) ) "),"JCRF") -> JCRF
B3: =IF($A2="","","Vendues : "& IF($A2="TOUTES", COUNTIF(Ventes!$D:$D,"*-*"), COUNTIF(Ventes!$D:$D,$A2&"-*") )& " pièces") -> Vendues : 26 pièces | C3: =IF($A2="","",IF($A2="TOUTES", SUMIF(Ventes!$D:$D,"*-*",Ventes!$F:$F), SUMIF(Ventes!$D:$D,$A2&"-*",Ventes!$F:$F) )) -> 331.3 | E3: =IFERROR(__xludf.DUMMYFUNCTION("""COMPUTED_VALUE"""),"JLF") -> JLF
E4: =IFERROR(__xludf.DUMMYFUNCTION("""COMPUTED_VALUE"""),"JLFK") -> JLFK
E5: =IFERROR(__xludf.DUMMYFUNCTION("""COMPUTED_VALUE"""),"JMHF") -> JMHF
E6: =IFERROR(__xludf.DUMMYFUNCTION("""COMPUTED_VALUE"""),"PCF") -> PCF
E7: =IFERROR(__xludf.DUMMYFUNCTION("""COMPUTED_VALUE"""),"PTHF") -> PTHF
E8: =IFERROR(__xludf.DUMMYFUNCTION("""COMPUTED_VALUE"""),"PTNFF") -> PTNFF
E9: =IFERROR(__xludf.DUMMYFUNCTION("""COMPUTED_VALUE"""),"SMHF") -> SMHF
E10: =IFERROR(__xludf.DUMMYFUNCTION("""COMPUTED_VALUE"""),"VMWNHF") -> VMWNHF
E11: =IFERROR(__xludf.DUMMYFUNCTION("""COMPUTED_VALUE"""),"VPHB") -> VPHB
E12: =IFERROR(__xludf.DUMMYFUNCTION("""COMPUTED_VALUE"""),"VTHF") -> VTHF
E13: TOUTES

Sheet Ventes
A1: ID | B1: DATE DE VENTE | C1: ARTICLE | D1: SKU | E1: FRAIS DE COLISSAGE | F1: PRIX VENTE | G1: DÉLAI D'IMMOBILISATION | H1: DELAI DE MISE EN LIGNE | I1: DELAI DE PUBLICATION | J1: DELAI DE VENTE | K1: RETOUR | L1: LOT
A2: 15 | B2: 45969 | C2: JEANS LEVIS Femme | D2: JLF-216 | E2: 0.11 | F2: 17.5 | G2: 0 | H2: 0 | I2: 0 | J2: 2
A3: 15 | B3: 45969 | C3: JEANS LEVIS Femme | D3: JLF-63 | E3: 0.11 | F3: 15 | G3: 0 | H3: 0 | I3: 0 | J3: 22
A4: 15 | B4: 45969 | C4: JEANS LEVIS Femme | D4: JLF-199 | E4: 0.11 | F4: 20 | G4: 0 | H4: 0 | I4: 0 | J4: 3
A5: 15 | B5: 45969 | C5: JEANS LEVIS Femme | D5: JLF-207 | E5: 0.11 | F5: 14.4 | G5: 0 | H5: 0 | I5: 0 | J5: 2
A6: 15 | B6: 45969 | C6: JEANS LEVIS Femme | D6: JLF-211 | E6: 0.11 | F6: 18 | G6: 0 | H6: 0 | I6: 0 | J6: 2
A7: 15 | B7: 45969 | C7: JEANS LEVIS Femme | D7: JLF-213 | E7: 0.11 | F7: 18 | G7: 0 | H7: 0 | I7: 0 | J7: 2
A8: 15 | B8: 45969 | C8: JEANS LEVIS Femme | D8: JLF-221 | E8: 0.11 | F8: 18 | G8: 0 | H8: 0 | I8: 0 | J8: 1
A9: 15 | B9: 45969 | C9: JEANS LEVIS Femme | D9: JLF-177 | E9: 0.11 | F9: 15 | G9: 0 | H9: 0 | I9: 0 | J9: 5
A10: 15 | B10: 45969 | C10: JEANS LEVIS Femme | D10: JLF-225 | E10: 0.11 | F10: 17.5 | G10: 0 | H10: 0 | I10: 0 | J10: 1
A11: 15 | B11: 45968 | C11: JEANS LEVIS Femme | D11: JLF-200 | E11: 0.11 | F11: 16.25 | G11: 0 | H11: 0 | I11: 0 | J11: 2
A12: 15 | B12: 45968 | C12: JEANS LEVIS Femme | D12: JLF-196 | E12: 0.11 | F12: 15 | G12: 0 | H12: 0 | I12: 0 | J12: 3
A13: 15 | B13: 45968 | C13: JEANS LEVIS Femme | D13: JLF-195 | E13: 0.11 | F13: 16.2 | G13: 0 | H13: 0 | I13: 0 | J13: 3
... A284: 3 | B284: 45901 | C284: VÊTEMENTS PERSO Homme/ Benoît | D284: VPHB-15 | E284: 0.11 | F284: 25 | G284: 0 | H284: 0 | I284: 0 | J284: 0

Sheet Compta 09-2025
A1: ID | B1: LIBELLÉS | C1: DATE DE VENTE | D1: MARGE BRUTE | E1: COEFF MARGE | F1: NBR PCS VENDU
A2: SEMAINE 1 01/09/2025 AU 07/09/2025
A3: 88 | B3: SNEAKERS MIX Homme/ Femme | C3: 45901 | D3: 16.82 | E3: 1.44 | F3: 1
A4: 3 | B4: VÊTEMENTS PERSO Homme/ Benoît | C4: 45901 | D4: 25 | F4: 1
A5: 2 | B5: VÊTEMENTS MIX WHAT NOT Homme/ Femme | C5: 45903 | D5: -0.55 | E5: 0.9 | F5: 1
A6: 2 | B6: VÊTEMENTS MIX WHAT NOT Homme/ Femme | C6: 45903 | D6: -0.55 | E6: 0.9 | F6: 1
A7: 2 | B7: VÊTEMENTS MIX WHAT NOT Homme/ Femme | C7: 45903 | D7: -1.55 | E7: 0.72 | F7: 1
A8: 2 | B8: VÊTEMENTS MIX WHAT NOT Homme/ Femme | C8: 45903 | D8: 6.45 | E8: 2.16 | F8: 1
A9: 89 | B9: SNEAKERS MIX Homme/ Femme | C9: 45903 | D9: 78.81 | E9: 8.04 | F9: 1
A10: 90 | B10: SNEAKERS MIX Homme/ Femme | C10: 45904 | D10: -3.54 | E10: 0.92 | F10: 1
A11: 2 | B11: VÊTEMENTS MIX WHAT NOT Homme/ Femme | C11: 45904 | D11: 17.45 | E11: 4.15 | F11: 1
A12: 2 | B12: VÊTEMENTS MIX WHAT NOT Homme/ Femme | C12: 45905 | D12: 7.45 | E12: 2.34 | F12: 1
A13: 2 | B13: VÊTEMENTS MIX WHAT NOT Homme/ Femme | C13: 45905 | D13: 12.05 | E13: 3.17 | F13: 1
A14: 91 | B14: SNEAKERS MIX Homme/ Femme | C14: 45906 | D14: -145 | E14: 0.24 | F14: 1
A15: TOTAL VENTE SEMAINE 1 : 12 | D15: 12.84 | E15: 2.27 | F15: 12
A17: SEMAINE 2 08/09/2025 AU 14/09/2025
A18: 4 | B18: JEANS LEVIS Femme/ Kevin | C18: 45909 | D18: 7.92 | E18: 2.12 | F18: 1
A19: 4 | B19: JEANS LEVIS Femme/ Kevin | C19: 45909 | D19: 8.92 | E19: 2.26 | F19: 1
A20: 4 | B20: JEANS LEVIS Femme/ Kevin | C20: 45909 | D20: 7.92 | E20: 2.12 | F20: 1
A21: 4 | B21: JEANS LEVIS Femme/ Kevin | C21: 45910 | D21: 7.87 | E21: 2.11 | F21: 1
A22: 4 | B22: JEANS LEVIS Femme/ Kevin | C22: 45910 | D22: 7.87 | E22: 2.11 | F22: 1
A23: 4 | B23: JEANS LEVIS Femme/ Kevin | C23: 45910 | D23: 9.92 | E23: 2.4 | F23: 1
A24: 3 | B24: VÊTEMENTS PERSO Homme/ Benoît | C24: 45911 | D24: 5 | F24: 1
A25: 4 | B25: JEANS LEVIS Femme/ Kevin | C25: 45911 | D25: 10.5 | E25: 2.48 | F25: 1
A26: 4 | B26: JEANS LEVIS Femme/ Kevin | C26: 45911 | D26: 10.5 | E26: 2.48 | F26: 1
A27: 4 | B27: JEANS LEVIS Femme/ Kevin | C27: 45913 | D27: 7.92 | E27: 2.12 | F27: 1
A28: 4 | B28: JEANS LEVIS Femme/ Kevin | C28: 45913 | D28: 4.92 | E28: 1.69 | F28: 1
A29: 4 | B29: JEANS LEVIS Femme/ Kevin | C29: 45914 | D29: 6.92 | E29: 1.98 | F29: 1
A30: 4 | B30: JEANS LEVIS Femme/ Kevin | C30: 45914 | D30: 7.87 | E30: 2.11 | F30: 1
A31: 4 | B31: JEANS LEVIS Femme/ Kevin | C31: 45914 | D31: 5.92 | E31: 1.84 | F31: 1
A32: 4 | B32: JEANS LEVIS Femme/ Kevin | C32: 45914 | D32: 6.92 | E32: 1.98 | F32: 1
A33: 92 | B33: SNEAKERS MIX Homme/ Femme | C33: 45914 | D33: -52.54 | E33: 0.37 | F33: 1
A34: 4 | B34: JEANS LEVIS Femme/ Kevin | C34: 45914 | D34: 12.92 | E34: 2.82 | F34: 1
A35: TOTAL VENTE SEMAINE 2 : 17 | D35: 77.27 | E35: 2.06 | F35: 17
A37: SEMAINE 3 15/09/2025 AU 21/09/2025
A38: 4 | B38: JEANS LEVIS Femme/ Kevin | C38: 45915 | D38: 11.92 | E38: 2.68 | F38: 1
A39: 4 | B39: JEANS LEVIS Femme/ Kevin | C39: 45915 | D39: 6.92 | E39: 1.98 | F39: 1
A40: 4 | B40: JEANS LEVIS Femme/ Kevin | C40: 45915 | D40: 6.92 | E40: 1.98 | F40: 1
A41: 4 | B41: JEANS LEVIS Femme/ Kevin | C41: 45915 | D41: 6.92 | E41: 1.98 | F41: 1
A42: 93 | B42: SNEAKERS MIX Homme/ Femme | C42: 45915 | D42: 121.25 | E42: 2.54 | F42: 1
...

Sheet Compta 10-2025
A1: ID | B1: LIBELLÉS | C1: DATE DE VENTE | D1: MARGE BRUTE | E1: COEFF MARGE | F1: NBR PCS VENDU
A2: SEMAINE 1 01/10/2025 AU 05/10/2025
A3: TOTAL VENTE SEMAINE 1
A5: SEMAINE 2 06/10/2025 AU 12/10/2025
A6: TOTAL VENTE SEMAINE 2
A8: SEMAINE 3 13/10/2025 AU 19/10/2025
A9: 14 | B9: JEANS LEVIS Femme | C9: 45946 | D9: 11.91 | E9: 2.68 | F9: 1
A10: 14 | B10: JEANS LEVIS Femme | C10: 45948 | D10: 11.91 | E10: 2.68 | F10: 1
A11: 14 | B11: JEANS LEVIS Femme | C11: 45948 | D11: 10.91 | E11: 2.54 | F11: 1
A12: 14 | B12: JEANS LEVIS Femme | C12: 45948 | D12: 7.91 | E12: 2.12 | F12: 1
A13: 14 | B13: JEANS LEVIS Femme | C13: 45948 | D13: 7.91 | E13: 2.12 | F13: 1
A14: 14 | B14: JEANS LEVIS Femme | C14: 45948 | D14: 10.41 | E14: 2.47 | F14: 1
A15: 14 | B15: JEANS LEVIS Femme | C15: 45948 | D15: 7.91 | E15: 2.12 | F15: 1
A16: 14 | B16: JEANS LEVIS Femme | C16: 45948 | D16: 11.91 | E16: 2.68 | F16: 1
A17: 14 | B17: JEANS LEVIS Femme | C17: 45948 | D17: 10.41 | E17: 2.47 | F17: 1
A18: 14 | B18: JEANS LEVIS Femme | C18: 45948 | D18: 10.91 | E18: 2.54 | F18: 1
A19: 5 | B19: VÊTEMENTS TYMAN Homme/ Femme | C19: 45948 | D19: 2.57 | E19: 2.8 | F19: 1
A20: 14 | B20: JEANS LEVIS Femme | C20: 45948 | D20: 8.91 | E20: 2.26 | F20: 1
... A39: 4 | B39: JEANS LEVIS Femme/ Kevin | C39: 45949 | D39: 4.92 | E39: 1.69 | F39: 1
A40: TOTAL VENTE SEMAINE 3 : 31 | D40: 285.52 | E40: 2.36 | F40: 31
A42: SEMAINE 4 20/10/2025 AU 26/10/2025
A43: 14 | B43: JEANS LEVIS Femme | C43: 45950 | D43: 9.16 | E43: 2.29 | F43: 1
A44: 14 | B44: JEANS LEVIS Femme | C44: 45950 | D44: 9.16 | E44: 2.29 | F44: 1
A45: 14 | B45: JEANS LEVIS Femme | C45: 45950 | D45: 11.91 | E45: 2.68 | F45: 1
A46: 14 | B46: JEANS LEVIS Femme | C46: 45950 | D46: 9.16 | E46: 2.29 | F46: 1
A47: 14 | B47: JEANS LEVIS Femme | C47: 45950 | D47: 9.16 | E47: 2.29 | F47: 1
A48: 14 | B48: JEANS LEVIS Femme | C48: 45950 | D48: 11.91 | E48: 2.68 | F48: 1
A49: 5 | B49: VÊTEMENTS TYMAN Homme/ Femme | C49: 45950 | D49: 13.57 | E49: 10.49 | F49: 1
A50: 14 | B50: JEANS LEVIS Femme | C50: 45951 | D50: 11.91 | E50: 2.68 | F50: 1
A51: 14 | B51: JEANS LEVIS Femme | C51: 45951 | D51: 10.01 | E51: 2.41 | F51: 1
A52: 14 | B52: JEANS LEVIS Femme | C52: 45951 | D52: 17.91 | E52: 3.53 | F52: 1
A53: 14 | B53: JEANS LEVIS Femme | C53: 45951 | D53: 10.91 | E53: 2.54 | F53: 1
A54: 14 | B54: JEANS LEVIS Femme | C54: 45952 | D54: 9.91 | E54: 2.4 | F54: 1
... A89: 15 | B89: JEANS LEVIS Femme | C89: 45956 | D89: 10.91 | E89: 2.53 | F89: 1
A90: TOTAL VENTE SEMAINE 4 : 47 | D90: 442.52 | E90: 2.65 | F90: 47
A92: SEMAINE 5 27/10/2025 AU 31/10/2025
A93: 13 | B93: PULL TOMMY HILFIGER Femme | C93: 45957 | D93: 8.46 | E93: 3.1 | F93: 1
A94: 13 | B94: PULL TOMMY HILFIGER Femme | C94: 45957 | D94: 8.46 | E94: 3.1 | F94: 1
A95: 13 | B95: PULL TOMMY HILFIGER Femme | C95: 45957 | D95: 11.96 | E95: 3.96 | F95: 1
A96: 13 | B96: PULL TOMMY HILFIGER Femme | C96: 45958 | D96: 7.96 | E96: 2.97 | F96: 1
...

Sheet Frais
A1: TAILLE DE COLIS | B1: FRAIS DE COLISSAGE | C1: LOT DE 2 | D1: LOT DE 3 | E1: LOT DE 4 | F1: LOT DE 5 | G1: LOT DE 6
A2: PETIT | B2: 0.11
A3: MOYEN | B3: 0.22 | C3: =B3/2 -> 0.11 | D3: =B3/3 -> 0.073333333
A4: GRAND | B4: 0.3 | C4: =B4/2 -> 0.15 | D4: =B4/3 -> 0.1 | E4: =B4/4 -> 0.075 | F4: =B4/5 -> 0.06 | G4: =B4/6 -> 0.05

Sheet Achatsmoisarticles

Sheet StockOld
A1: ARTICLES(1) | B1: MARQUE | C1: GENRE | D1: DATE ACHAT | E1: ARTICLE(0) | F1: SKU | G1: PRIX ACHAT | H1: DATE DE MISE EN LIGNE ESTIMÉE | I1: VENDU | J1: DATE DE VENTE | K1: PRIX VENTE | L1: DÉLAI DE VENTE (EN JOURS) | M1: MARGE BRUTE | N1: COEFF MARGE
E2: SNEAKERS | G2: 3 | H2: 45858 | I2: FALSE | L2: =IF(ISBLANK(J2),"",J2-H2) | M2: =IF(K2="","",IF(K2-G2<0,"",K2-G2)) | N2: =IF(K2="","",IF(K2/G2<0,"",K2/G2))
E3: SNEAKERS | G3: 25 | H3: 45886 | I3: FALSE | L3: =IF(ISBLANK(J3),"",J3-H3) | M3: =IF(K3="","",IF(K3-G3<0,"",K3-G3)) | N3: =IF(K3="","",IF(K3/G3<0,"",K3/G3))
E4: SNEAKERS NEW B 237 | G4: 9.39 | H4: 45901 | I4: FALSE | L4: =IF(ISBLANK(J4),"",J4-H4) | M4: =IF(K4="","",IF(K4-G4<0,"",K4-G4)) | N4: =IF(K4="","",IF(K4/G4<0,"",K4/G4))
I5: FALSE
E6: VETEMENT 1 | F6: VPB-1 | G6: 0 | H6: 45896 | I6: FALSE | L6: =IF(ISBLANK(J6),"",J6-H6) | M6: =IF(K6="","",IF(K6-G6<0,"",K6-G6)) | N6: =IF(K6="","",IF(K6/G6<0,"",K6/G6))
E7: VETEMENT 2 | F7: VPB-2 | G7: 0 | H7: 45901 | I7: FALSE | L7: =IF(ISBLANK(J7),"",J7-H7) | M7: =IF(K7="","",IF(K7-G7<0,"",K7-G7)) | N7: =IF(K7="","",IF(K7/G7<0,"",K7/G7))
E8: VETEMENT 3 | F8: VPB-3 | G8: 0 | H8: 45901 | I8: FALSE | L8: =IF(ISBLANK(J8),"",J8-H8) | M8: =IF(K8="","",IF(K8-G8<0,"",K8-G8)) | N8: =IF(K8="","",IF(K8/G8<0,"",K8/G8))
E9: VETEMENT 4 | F9: VPB-4 | G9: 0 | H9: 45901 | I9: FALSE | L9: =IF(ISBLANK(J9),"",J9-H9) | M9: =IF(K9="","",IF(K9-G9<0,"",K9-G9)) | N9: =IF(K9="","",IF(K9/G9<0,"",K9/G9))
E10: VETEMENT 5 | F10: VPB-5 | G10: 0 | H10: 45901 | I10: FALSE | L10: =IF(ISBLANK(J10),"",J10-H10) | M10: =IF(K10="","",IF(K10-G10<0,"",K10-G10)) | N10: =IF(K10="","",IF(K10/G10<0,"",K10/G10))
E11: VETEMENT 6 | F11: VPB-6 | G11: 0 | H11: 45901 | I11: FALSE | L11: =IF(ISBLANK(J11),"",J11-H11) | M11: =IF(K11="","",IF(K11-G11<0,"",K11-G11)) | N11: =IF(K11="","",IF(K11/G11<0,"",K11/G11))
E12: VETEMENT 7 | F12: VPB-7 | G12: 0 | H12: 45901 | I12: FALSE | L12: =IF(ISBLANK(J12),"",J12-H12) | M12: =IF(K12="","",IF(K12-G12<0,"",K12-G12)) | N12: =IF(K12="","",IF(K12/G12<0,"",K12/G12))
E13: VETEMENT 8 | F13: VPB-8 | G13: 0 | H13: 45901 | I13: FALSE | L13: =IF(ISBLANK(J13),"",J13-H13) | M13: =IF(K13="","",IF(K13-G13<0,"",K13-G13)) | N13: =IF(K13="","",IF(K13/G13<0,"",K13/G13))
I14: FALSE
A15: JEANS | E15: JEANS LEVIS FEMME | F15: JLFK-0825-21 | G15: 7.18 | H15: 45904 | I15: FALSE | L15: =IF(ISBLANK(J15),"",J15-H15) | M15: =IF(K15="","",IF(K15-G15<0,"",K15-G15)) | N15: =IF(K15="","",IF(K15/G15<0,"",K15/G15))
E16: JEANS LEVIS FEMME | F16: JLFK-0825-27 | G16: 7.18 | H16: 45904 | I16: FALSE | L16: =IF(ISBLANK(J16),"",J16-H16) | M16: =IF(K16="","",IF(K16-G16<0,"",K16-G16)) | N16: =IF(K16="","",IF(K16/G16<0,"",K16/G16))
E17: JEANS LEVIS FEMME | F17: JLFK-0825-31 | G17: 7.18 | H17: 45904 | I17: FALSE | L17: =IF(ISBLANK(J17),"",J17-H17) | M17: =IF(K17="","",IF(K17-G17<0,"",K17-G17)) | N17: =IF(K17="","",IF(K17/G17<0,"",K17/G17))
E18: JEANS LEVIS FEMME | F18: JLFK-0825-32 | G18: 7.18 | H18: 45904 | I18: FALSE | L18: =IF(ISBLANK(J18),"",J18-H18) | M18: =IF(K18="","",IF(K18-G18<0,"",K18-G18)) | N18: =IF(K18="","",IF(K18/G18<0,"",K18/G18))
E19: JEANS LEVIS FEMME | F19: JLFK-0825-33 | G19: 7.18 | H19: 45904 | I19: FALSE | L19: =IF(ISBLANK(J19),"",J19-H19) | M19: =IF(K19="","",IF(K19-G19<0,"",K19-G19)) | N19: =IF(K19="","",IF(K19/G19<0,"",K19/G19))
E20: JEANS LEVIS FEMME | F20: JLFK-0825-37 | G20: 7.18 | H20: 45904 | I20: FALSE | M20: =IF(K20="","",IF(K20-G20<0,"",K20-G20)) | N20: =IF(K20="","",IF(K20/G20<0,"",K20/G20))
E21: JEANS LEVIS FEMME | F21: JLFK-0825-44 | G21: 7.18 | H21: 45904 | I21: FALSE | L21: =IF(ISBLANK(J21),"",J21-H21) | M21: =IF(K21="","",IF(K21-G21<0,"",K21-G21)) | N21: =IF(K21="","",IF(K21/G21<0,"",K21/G21))
E22: JEANS LEVIS FEMME | F22: JLFK-0825-46 | G22: 7.18 | H22: 45904 | I22: FALSE | L22: =IF(ISBLANK(J22),"",J22-H22) | M22: =IF(K22="","",IF(K22-G22<0,"",K22-G22)) | N22: =IF(K22="","",IF(K22/G22<0,"",K22/G22))
E23: JEANS LEVIS FEMME | F23: JLFK-0825-55 | G23: 7.18 | H23: 45904 | I23: FALSE | L23: =IF(ISBLANK(J23),"",J23-H23) | M23: =IF(K23="","",IF(K23-G23<0,"",K23-G23)) | N23: =IF(K23="","",IF(K23/G23<0,"",K23/G23))
E24: JEANS LEVIS FEMME | F24: JLFK-0825-60 | G24: 7.18 | H24: 45904 | I24: FALSE | L24: =IF(ISBLANK(J24),"",J24-H24) | M24: =IF(K24="","",IF(K24-G24<0,"",K24-G24)) | N24: =IF(K24="","",IF(K24/G24<0,"",K24/G24))
E25: JEANS LEVIS FEMME | F25: JLFK-0825-65 | G25: 7.18 | H25: 45904 | I25: FALSE | L25: =IF(ISBLANK(J25),"",J25-H25) | M25: =IF(K25="","",IF(K25-G25<0,"",K25-G25)) | N25: =IF(K25="","",IF(K25/G25<0,"",K25/G25))
E26: JEANS LEVIS FEMME | F26: JLFK-0825-69 | G26: 7.18 | H26: 45904 | I26: FALSE | L26: =IF(ISBLANK(J26),"",J26-H26) | M26: =IF(K26="","",IF(K26-G26<0,"",K26-G26)) | N26: =IF(K26="","",IF(K26/G26<0,"",K26/G26))
E27: JEANS LEVIS FEMME | F27: JLFK-0825-70 | G27: 7.18 | H27: 45904 | I27: FALSE | L27: =IF(ISBLANK(J27),"",J27-H27) | M27: =IF(K27="","",IF(K27-G27<0,"",K27-G27)) | N27: =IF(K27="","",IF(K27/G27<0,"",K27/G27))
E28: JEANS LEVIS FEMME | F28: JLFK-0825-72 | G28: 7.18 | H28: 45904 | I28: FALSE | L28: =IF(ISBLANK(J28),"",J28-H28) | M28: =IF(K28="","",IF(K28-G28<0,"",K28-G28)) | N28: =IF(K28="","",IF(K28/G28<0,"",K28/G28))
E29: JEANS LEVIS FEMME | F29: JLFK-0825-74 | G29: 7.18 | H29: 45904 | I29: FALSE | L29: =IF(ISBLANK(J29),"",J29-H29) | M29: =IF(K29="","",IF(K29-G29<0,"",K29-G29)) | N29: =IF(K29="","",IF(K29/G29<0,"",K29/G29))
I30: FALSE
E31: VETEMENT DIVERS FEMME | F31: VDF-0825-8 | G31: 1.42 | H31: 45906 | I31: FALSE | L31: =IF(ISBLANK(J31),"",J31-H31) | M31: =IF(K31="","",IF(K31-G31<0,"",K31-G31)) | N31: =IF(K31="","",IF(K31/G31<0,"",K31/G31))
E32: VETEMENT DIVERS FEMME | F32: VDF-0825-9 | G32: 1.42 | H32: 45906 | I32: FALSE | L32: =IF(ISBLANK(J32),"",J32-H32) | M32: =IF(K32="","",IF(K32-G32<0,"",K32-G32)) | N32: =IF(K32="","",IF(K32/G32<0,"",K32/G32))
E33: VETEMENT DIVERS FEMME | F33: VDF-0825-10 | G33: 1.42 | H33: 45906 | I33: FALSE | L33: =IF(ISBLANK(J33),"",J33-H33) | M33: =IF(K33="","",IF(K33-G33<0,"",K33-G33)) | N33: =IF(K33="","",IF(K33/G33<0,"",K33/G33))
E34: VETEMENT DIVERS FEMME | F34: VDF-0825-11 | G34: 1.42 | H34: 45906 | I34: FALSE | L34: =IF(ISBLANK(J34),"",J34-H34) | M34: =IF(K34="","",IF(K34-G34<0,"",K34-G34)) | N34: =IF(K34="","",IF(K34/G34<0,"",K34/G34))
E35: VETEMENT DIVERS FEMME | F35: VDF-0825-12 | G35: 1.42 | H35: 45906 | I35: FALSE | L35: =IF(ISBLANK(J35),"",J35-H35) | M35: =IF(K35="","",IF(K35-G35<0,"",K35-G35)) | N35: =IF(K35="","",IF(K35/G35<0,"",K35/G35))
E36: VETEMENT DIVERS FEMME | F36: VDF-0825-13 | G36: 1.42 | H36: 45906 | I36: FALSE | L36: =IF(ISBLANK(J36),"",J36-H36) | M36: =IF(K36="","",IF(K36-G36<0,"",K36-G36)) | N36: =IF(K36="","",IF(K36/G36<0,"",K36/G36))
E37: VETEMENT DIVERS FEMME | F37: VDF-0825-14 | G37: 1.42 | H37: 45906 | I37: FALSE | L37: =IF(ISBLANK(J37),"",J37-H37) | M37: =IF(K37="","",IF(K37-G37<0,"",K37-G37)) | N37: =IF(K37="","",IF(K37/G37<0,"",K37/G37))
E38: VETEMENT DIVERS FEMME | F38: VDF-0825-15 | G38: 1.42 | H38: 45906 | I38: FALSE | L38: =IF(ISBLANK(J38),"",J38-H38) | M38: =IF(K38="","",IF(K38-G38<0,"",K38-G38)) | N38: =IF(K38="","",IF(K38/G38<0,"",K38/G38))
E39: VETEMENT DIVERS FEMME | F39: VDF-0825-16 | G39: 1.42 | H39: 45906 | I39: FALSE | L39: =IF(ISBLANK(J39),"",J39-H39) | M39: =IF(K39="","",IF(K39-G39<0,"",K39-G39)) | N39: =IF(K39="","",IF(K39/G39<0,"",K39/G39))
E40: VETEMENT DIVERS FEMME | F40: VDF-0825-17 | G40: 1.42 | H40: 45906 | I40: FALSE | L40: =IF(ISBLANK(J40),"",J40-H40) | M40: =IF(K40="","",IF(K40-G40<0,"",K40-G40)) | N40: =IF(K40="","",IF(K40/G40<0,"",K40/G40))
...

Sheet Ventes(old)
A1: ID | B1: LIBELLÉS | C1: DATE DE VENTE | D1: MARGE BRUTE | E1: COEFF MARGE | F1: NBR PCS VENDU
B2: SEMAINE 1 01/10/2025 AU 05/10/2025 | E2: =IF(#REF!="","",IF(#REF!/#REF!<0,"",#REF!/#REF!)) -> #REF!
A3: 6 | B3: JACKET MIX MARQUES GRADE B JMB-099 | C3: 45931 | D3: =IF(#REF!="","",IF(#REF!-#REF!<0,"",#REF!-#REF!)) -> #REF! | E3: =IF(#REF!="","",IF(#REF!/#REF!<0,"",#REF!/#REF!)) -> #REF!
A4: 6 | B4: JACKET MIX MARQUES GRADE B JMB-127 | C4: 45932 | D4: =IF(#REF!="","",IF(#REF!-#REF!<0,"",#REF!-#REF!)) -> #REF! | E4: =IF(#REF!="","",IF(#REF!/#REF!<0,"",#REF!/#REF!)) -> #REF!
B5: JEANS LEVIS FEMME JLFK-35 | C5: 45934 | D5: =IF(#REF!="","",IF(#REF!-#REF!<0,"",#REF!-#REF!)) -> #REF! | E5: =IF(#REF!="","",IF(#REF!/#REF!<0,"",#REF!/#REF!)) -> #REF!
B6: VETEMENT HOMME TYMAN 7 | C6: 45935 | D6: =IF(#REF!="","",IF(#REF!-#REF!<0,"",#REF!-#REF!)) -> #REF! | E6: =IF(#REF!="","",IF(#REF!/#REF!<0,"",#REF!/#REF!)) -> #REF!
B7: JACKET MIX MARQUES GRADE B JMB-091 | C7: 45935 | D7: =IF(#REF!="","",IF(#REF!-#REF!<0,"",#REF!-#REF!)) -> #REF! | E7: =IF(#REF!="","",IF(#REF!/#REF!<0,"",#REF!/#REF!)) -> #REF!
B8: JACKET MIX MARQUES GRADE B JMB-119 | C8: 45935 | D8: =IF(#REF!="","",IF(#REF!-#REF!<0,"",#REF!-#REF!)) -> #REF! | E8: =IF(#REF!="","",IF(#REF!/#REF!<0,"",#REF!/#REF!)) -> #REF!
B9: JACKET MIX MARQUES GRADE B JMB-126 | C9: 45935 | D9: =IF(#REF!="","",IF(#REF!-#REF!<0,"",#REF!-#REF!)) -> #REF! | E9: =IF(#REF!="","",IF(#REF!/#REF!<0,"",#REF!/#REF!)) -> #REF!
B10: JACKET MIX MARQUES GRADE B JMB-131 | C10: 45935 | D10: =IF(#REF!="","",IF(#REF!-#REF!<0,"",#REF!-#REF!)) -> #REF! | E10: =IF(#REF!="","",IF(#REF!/#REF!<0,"",#REF!/#REF!)) -> #REF!
B11: JACKET MIX MARQUES GRADE B JMB-135 | C11: 45935 | D11: =IF(#REF!="","",IF(#REF!-#REF!<0,"",#REF!-#REF!)) -> #REF! | E11: =IF(#REF!="","",IF(#REF!/#REF!<0,"",#REF!/#REF!)) -> #REF!
B12: JACKET MIX MARQUES GRADE B JMB-136 | C12: 45935 | D12: =IF(#REF!="","",IF(#REF!-#REF!<0,"",#REF!-#REF!)) -> #REF! | E12: =IF(#REF!="","",IF(#REF!/#REF!<0,"",#REF!/#REF!)) -> #REF!
B13: =("TOTAL VENTE SEMAINE 1 : " & COUNTA(#REF!) ) -> TOTAL VENTE SEMAINE 1 : 1 | D13: =SUM(D3:D12) -> #REF! | E13: =AVERAGE(E3:E12) -> #REF! | F13: =COUNTA(#REF!) -> 1
B15: SEMAINE 2 06/10/2025 AU 12/10/2025
B16: SNEAKERS | C16: 45937 | D16: =IF(#REF!="","",IF(#REF!-#REF!<0,"",#REF!-#REF!)) -> #REF!
B17: JEANS LEVIS FEMME JLFK-43 | C17: 45939 | D17: =IF(#REF!="","",IF(#REF!-#REF!<0,"",#REF!-#REF!)) -> #REF! | E17: =IF(#REF!="","",IF(#REF!/#REF!<0,"",#REF!/#REF!)) -> #REF!
B18: JEANS LEVIS FEMME JLFK-51 | C18: 45937 | D18: =IF(#REF!="","",IF(#REF!-#REF!<0,"",#REF!-#REF!)) -> #REF! | E18: =IF(#REF!="","",IF(#REF!/#REF!<0,"",#REF!/#REF!)) -> #REF!
B19: JEANS LEVIS FEMME JLFK-79 | C19: 45938 | D19: =IF(#REF!="","",IF(#REF!-#REF!<0,"",#REF!-#REF!)) -> #REF! | E19: =IF(#REF!="","",IF(#REF!/#REF!<0,"",#REF!/#REF!)) -> #REF!
B20: JACKET MIX MARQUES GRADE B JMB-111 | C20: 45941 | D20: =IF(#REF!="","",IF(#REF!-#REF!<0,"",#REF!-#REF!)) -> #REF! | E20: =IF(#REF!="","",IF(#REF!/#REF!<0,"",#REF!/#REF!)) -> #REF!
B21: JACKET MIX MARQUES GRADE B JMB-116 | C21: 45937 | D21: =IF(#REF!="","",IF(#REF!-#REF!<0,"",#REF!-#REF!)) -> #REF! | E21: =IF(#REF!="","",IF(#REF!/#REF!<0,"",#REF!/#REF!)) -> #REF!
B22: JACKET MIX MARQUES GRADE B JMB-124 | C22: 45940 | D22: =IF(#REF!="","",IF(#REF!-#REF!<0,"",#REF!-#REF!)) -> #REF! | E22: =IF(#REF!="","",IF(#REF!/#REF!<0,"",#REF!/#REF!)) -> #REF!
B23: JEAN LEVIS FEMME JLF1 | C23: 45941 | D23: =IF(#REF!="","",IF(#REF!-#REF!<0,"",#REF!-#REF!)) -> #REF! | E23: =IF(#REF!="","",IF(#REF!/#REF!<0,"",#REF!/#REF!)) -> #REF!
B24: JEAN LEVIS FEMME JLF3 | C24: 45941 | D24: =IF(#REF!="","",IF(#REF!-#REF!<0,"",#REF!-#REF!)) -> #REF! | E24: =IF(#REF!="","",IF(#REF!/#REF!<0,"",#REF!/#REF!)) -> #REF!
B25: JEAN LEVIS FEMME JLF4 | C25: 45941 | D25: =IF(#REF!="","",IF(#REF!-#REF!<0,"",#REF!-#REF!)) -> #REF! | E25: =IF(#REF!="","",IF(#REF!/#REF!<0,"",#REF!/#REF!)) -> #REF!
B26: JEAN LEVIS FEMME JLF5 | C26: 45942 | D26: =IF(#REF!="","",IF(#REF!-#REF!<0,"",#REF!-#REF!)) -> #REF! | E26: =IF(#REF!="","",IF(#REF!/#REF!<0,"",#REF!/#REF!)) -> #REF!
B27: JEAN LEVIS FEMME JLF6 | C27: 45942 | D27: =IF(#REF!="","",IF(#REF!-#REF!<0,"",#REF!-#REF!)) -> #REF! | E27: =IF(#REF!="","",IF(#REF!/#REF!<0,"",#REF!/#REF!)) -> #REF!
B28: JEAN LEVIS FEMME JLF8 | C28: 45941 | D28: =IF(#REF!="","",IF(#REF!-#REF!<0,"",#REF!-#REF!)) -> #REF! | E28: =IF(#REF!="","",IF(#REF!/#REF!<0,"",#REF!/#REF!)) -> #REF!
B29: SNEAKERS | C29: 45937 | D29: =IF(#REF!="","",IF(#REF!-#REF!<0,"",#REF!-#REF!)) -> #REF!
B30: JEAN LEVIS FEMME JLF17 | C30: 45942 | D30: =IF(#REF!="","",IF(#REF!-#REF!<0,"",#REF!-#REF!)) -> #REF! | E30: =IF(#REF!="","",IF(#REF!/#REF!<0,"",#REF!/#REF!)) -> #REF!
B31: =("TOTAL VENTE SEMAINE 2 : " & COUNTA(#REF!) ) -> TOTAL VENTE SEMAINE 2 : 1 | D31: =SUM(D16:D30) -> #REF! | E31: =AVERAGE(E22:E30) -> #REF! | F31: =COUNTA(#REF!) -> 1
B33: SEMAINE 3 13/10/2025 au 19/10/2025
B34: JEAN LEVIS FEMME JLF2 | C34: 45943 | D34: =IF(#REF!="","",IF(#REF!-#REF!<0,"",#REF!-#REF!)) -> #REF! | E34: =IF(#REF!="","",IF(#REF!/#REF!<0,"",#REF!/#REF!)) -> #REF!
B35: JEAN LEVIS FEMME JLF18 | C35: 45943 | D35: =IF(#REF!="","",IF(#REF!-#REF!<0,"",#REF!-#REF!)) -> #REF! | E35: =IF(#REF!="","",IF(#REF!/#REF!<0,"",#REF!/#REF!)) -> #REF!
B36: JEAN LEVIS FEMME JLF22 | C36: 45943 | D36: =IF(#REF!="","",IF(#REF!-#REF!<0,"",#REF!-#REF!)) -> #REF! | E36: =IF(#REF!="","",IF(#REF!/#REF!<0,"",#REF!/#REF!)) -> #REF!
B37: JEAN LEVIS FEMME JLF27 | C37: 45943 | D37: =IF(#REF!="","",IF(#REF!-#REF!<0,"",#REF!-#REF!)) -> #REF! | E37: =IF(#REF!="","",IF(#REF!/#REF!<0,"",#REF!/#REF!)) -> #REF!
B38: JACKET MIX MARQUES GRADE B JMB-087 | C38: 45944 | D38: =IF(#REF!="","",IF(#REF!-#REF!<0,"",#REF!-#REF!)) -> #REF! | E38: =IF(#REF!="","",IF(#REF!/#REF!<0,"",#REF!/#REF!)) -> #REF!
B39: SNEAKERS | C39: 45945 | D39: =IF(#REF!="","",IF(#REF!-#REF!<0,"",#REF!-#REF!)) -> #REF! | E39: =IF(#REF!="","",IF(#REF!/#REF!<0,"",#REF!/#REF!)) -> #REF!
B40: JEANS LEVIS FEMME JLFK-56 | C40: 45945 | D40: =IF(#REF!="","",IF(#REF!-#REF!<0,"",#REF!-#REF!)) -> #REF! | E40: =IF(#REF!="","",IF(#REF!/#REF!<0,"",#REF!/#REF!)) -> #REF!
B41: JEAN LEVIS FEMME JLF23 | C41: 45945 | D41: =IF(#REF!="","",IF(#REF!-#REF!<0,"",#REF!-#REF!)) -> #REF! | E41: =IF(#REF!="","",IF(#REF!/#REF!<0,"",#REF!/#REF!)) -> #REF!
B42: JEAN LEVIS FEMME JLF26 | C42: 45945 | D42: =IF(#REF!="","",IF(#REF!-#REF!<0,"",#REF!-#REF!)) -> #REF! | E42: =IF(#REF!="","",IF(#REF!/#REF!<0,"",#REF!/#REF!)) -> #REF!
...

Sheet Comptabilité
A1: COMPTABILITÉ
A3: SORTIE | D3: ENTRÉE | G3: STOCK
A4: DÉPENSE | B4: MONTANT | D4: CA VENTE | E4: =SUM('STOCK VENDU'!F13,'STOCK VENDU'!F30,'STOCK VENDU'!F79,'STOCK VENDU'!F129,'STOCK VENDU'!F158) -> #REF! | G4: VALEUR DE STOCK | H4: =SUM(StockOld!G2:G368) -> 2290.68
A5: CLEMZ | B5: 0
A6: CHATGPT | B6: 22.99 | D6: MARGE BRUT | E6: =SUM('STOCK VENDU'!H13,'STOCK VENDU'!H30,'STOCK VENDU'!H79,'STOCK VENDU'!H129,'STOCK VENDU'!H158) -> #REF!
A7: REVOLUT | B7: 9.99 | D7: COEFF MARGE | E7: =AVERAGE('STOCK VENDU'!I13,'STOCK VENDU'!I30,'STOCK VENDU'!I79,'STOCK VENDU'!I129,'STOCK VENDU'!I158) -> #REF!
A8: CONEVERT LABEL | B8: 1 | D8: WHATNOT
A9: DRESSING VINTED | B9: =8.01+7.87+8.73+8.95 -> 33.56
A10: BOOST | B10: =12.59+3.86+6.2+4.24+8.68 -> 35.57 | D10: CA TOTAL | E10: =SUM(E4,E8) -> #REF!
A11: ESSENCE livraison, lavomatique, etc | B11: 50
A12: LAVERIE (machine+séche linge) | B12: =128.8+26+15.33+7.66 -> 177.79 | D12: MARGE BRUT TOTAL | E12: =SUM(E6,E8) -> #REF!
A13: NETTOYANT lessive, adoucissant, decolor stop,détachant | B13: 16
A14: FOURNITURE DE BUREAU pochettes d'envoie, bordereau | B14: 30
A15: TEMU x2 double portant, | B15: 50.21
A16: AMAZON eau, cintres, rouleau a poile | B16: =17.94+53.85 -> 71.79
A17: BRICOLAGE planche armoire | B17: 30
A18: TOTAL DÉPENSE | B18: =SUM(B6:B17) -> 528.9
A21: BÉNÉFICE MOIS | B21: =SUM(E8,E6) -> #REF!
A22: BENEFICE MOIS - TOTAL DEPENSE | B22: =SUM(B21-B18) -> #REF!
G24: 45904
G25: 45899
G26: 45906
G27: 45924
G28: 45960
G29: 45960
G30: 45960
G31: 45960
G32: 45960
G34: 45960
G35: 45960
