Workbook
Name MARQUES: Achats!$C$4:$C$18
Name GENRE: Achats!$E$4:$E$18
Name ARTICLES: Achats!$B$4:$B$18
Name DATE_ACHAT: Achats!$F$4:$F$18
Name SKU: Achats!$G$4:$G$18

Sheet Suivi stockvaleurs
A1: Références | B1: Quantité | C1: Valeurs | D1: Marge | E1: SKU's
A2: JLF | B2: =IF($A2="","","En stock : "& IF($A2="TOUTES", COUNTIF(Stock!$D:$D,"*-*"), COUNTIF(Stock!$D:$D,$A2&"-*") )& " pièces") -> En stock : 180 pièces | C2: =IF($A2="","",IF( $A2="TOUTES", SUMPRODUCT( (Stock!$D$2:$D1000<>"") * IFERROR(VLOOKUP(Stock!$A$2:$A1000,Achats!$A$2:$T1000,20,FALSE),0) ), COUNTIF(Stock!$D:$D,$A2&"-*") * IFERROR(VLOOKUP($A2,Achats!$G:$T,14,FALSE),0) )) -> 1275.6375 | D2: =IF($A2="","","Estimée à "&TEXT(C2,"0,00 €")& " (~"&TEXT(C2/C2,"0%")&")") -> Estimée à 1 276 € (~100%) | E2: =IFERROR(__xludf.DUMMYFUNCTION("SORT( UNIQUE( FILTER( Achats!$G$2:$G1000, Achats!$G$2:$G1000<>"""" ) ) ) "),"JCR") -> JCR
B3: =IF($A2="","","Vendues : "& IF($A2="TOUTES", COUNTIF(Ventes!$D:$D,"*-*"), COUNTIF(Ventes!$D:$D,$A2&"-*") )& " pièces") -> Vendues : 156 pièces | C3: =IF($A2="","",IF($A2="TOUTES", SUMIF(Ventes!$D:$D,"*-*",Ventes!$F:$F), SUMIF(Ventes!$D:$D,$A2&"-*",Ventes!$F:$F) )) -> 2606.09 | D3: =IF($A2="","" , IF($A2="TOUTES" , LET( ventes, SUM(Ventes!$F$2:$F$1002) , marge, SUMPRODUCT( (Ventes!$D$2:$D$1002<>"") * ( Ventes!$F$2:$F$1002 - IFERROR( VLOOKUP( LEFT(Ventes!$D$2:$D$1002,SEARCH("-",Ventes!$D$2:$D$1002)-1) , Achats!$G$2:$T$1000 , 14 , FALSE ) , 0 ) ) ) , cout, ventes - marge , ""&TEXT(marge,"0,00 €")& " ("&TEXT(marge/cout,"0%")&")" ) , LET( ventes, SUMIF(Ventes!$D:$D,$A2&"-*",Ventes!$F:$F) , marge, ventes - COUNTIF(Ventes!$D:$D,$A2&"-*") * IFERROR(VLOOKUP($A2,Achats!$G:$T,14,FALSE),0) , cout, ventes - marge , ""&TEXT(marge,"0,00 €")& " ("&TEXT(marge/cout,"0%")&")" ) ) ) -> 1 501 € (136%) | E3: =IFERROR(__xludf.DUMMYFUNCTION("""COMPUTED_VALUE"""),"JLF") -> JLF
E4: =IFERROR(__xludf.DUMMYFUNCTION("""COMPUTED_VALUE"""),"JLFK") -> JLFK
E5: =IFERROR(__xludf.DUMMYFUNCTION("""COMPUTED_VALUE"""),"JMB") -> JMB
E6: =IFERROR(__xludf.DUMMYFUNCTION("""COMPUTED_VALUE"""),"PC") -> PC
E7: =IFERROR(__xludf.DUMMYFUNCTION("""COMPUTED_VALUE"""),"PTF") -> PTF
E8: =IFERROR(__xludf.DUMMYFUNCTION("""COMPUTED_VALUE"""),"PTNF") -> PTNF
E9: =IFERROR(__xludf.DUMMYFUNCTION("""COMPUTED_VALUE"""),"SM") -> SM
E10: =IFERROR(__xludf.DUMMYFUNCTION("""COMPUTED_VALUE"""),"VPHB") -> VPHB
E11: =IFERROR(__xludf.DUMMYFUNCTION("""COMPUTED_VALUE"""),"VTF") -> VTF
E12: =IFERROR(__xludf.DUMMYFUNCTION("""COMPUTED_VALUE"""),"VTH") -> VTH
E13: =IFERROR(__xludf.DUMMYFUNCTION("""COMPUTED_VALUE"""),"VWN") -> VWN
E14: TOUTES

Sheet Achats
A1: ID | B1: ARTICLES | C1: MARQUE | D1: GENRE | E1: =IFERROR(__xludf.DUMMYFUNCTION("{""GENRE(data)""; MAP(D2:D19, LAMBDA(c, IF(c="""", """", IF(REGEXMATCH(c,""♀️ */ *♂️""),""Homme/ Femme"", IF(REGEXMATCH(c,""♀️ */ *Kevin""),""Femme/ Kevin"", IF(REGEXMATCH(c,""♂️ */ *Beno[îi]t""),""Homme/ Benoît"&""", IF(REGEXMATCH(c,""♀️""),""Femme"", IF(REGEXMATCH(c,""♂️""),""Homme"",""""))))) ) ) ) } "),"GENRE(data)") -> GENRE(data) | F1: DATE D'ACHAT | G1: =IFERROR(__xludf.DUMMYFUNCTION("{""REFERENCE""; MAP(B2:B19, C2:C19, E2:E19, LAMBDA(a, b, c, IF(AND(a="""", b="""", c=""""), """", LET( ACR, LAMBDA(x, SUBSTITUTE(REGEXREPLACE("" ""&UPPER(TRIM(x)),""(^| )([A-ZÀ-ÖØ-öø-ÿ])[^ ]*"",""$2""),"" "","""")), acrA, ACR(a), "&" acrB, ACR(b), uc, UPPER(TRIM(c)), norm, REGEXREPLACE(uc, ""\s*/\s*"", ""/""), ban, REGEXMATCH(norm, ""^HOMME/FEMME$""), allow, AND(NOT(ban), REGEXMATCH(norm, ""^(HOMME|FEMME)$|^HOMME/BENO[IÎ]T$|^FEMME/KEVIN$"")), acrC, "&"IF(allow, IF(REGEXMATCH(norm, ""/""), ACR(INDEX(SPLIT(norm, ""/""), 1, 1)) & ACR(INDEX(SPLIT(norm, ""/""), 1, 2)), ACR(norm) ), """" ), T"&"EXTJOIN("""" , TRUE, acrA, acrB, acrC) ) ) ) )} "),"REFERENCE") -> REFERENCE | H1: GRADE | I1: FOURNISSEUR/CODE | J1: {={"MOIS"; IF(F4:F19="","", UPPER(TEXT(F4:F19,"mmmm")) )}} -> MOIS | K1: {={"MOIS NUM"; IF(F4:F19="", "", TEXT(MONTH(F4:F19),"00"))}} -> MOIS NUM | L1: DATE DE LIVRAISON | M1: {={"DELAI DE LIVRAISON";IF(L2:L19="","",L2:L19-F2:F19)}} -> DELAI DE LIVRAISON | N1: PRIX D'ACHAT SHIP INCLUS | O1: QUANTITÉ COMMANDÉE | P1: QUANTITÉ RECUE | Q1: {={"PRIX UNITAIRE BRUTE";IF(P2:P19="","",N2:N19/P2:P19)}} -> PRIX UNITAIRE BRUTE | R1: FRAIS DE LAVAGE | S1: TOTAL TTC | T1: {={"PRIX UNITAIRE TTC";IF(P2:P19="","",S2:S19/P2:P19)}} -> PRIX UNITAIRE TTC | U1: TRACKING | V1: PRÊT POUR MISE EN STOCK | DATE
A2: 1 | B2: SNEAKERS | C2: MIX | D2: ♀️ / ♂️ | E2: =IFERROR(__xludf.DUMMYFUNCTION("""COMPUTED_VALUE"""),"Homme/ Femme") -> Homme/ Femme | F2: 45889 | G2: =IFERROR(__xludf.DUMMYFUNCTION("""COMPUTED_VALUE"""),"SM") -> SM | H2: A | I2: WHAT NOT/VINTED | J2: FÉVRIER | K2: 02 | L2: 45898 | M2: 9 | N2: 808.57 | O2: 17 | P2: 17 | Q2: 47.562941 | R2: 0 | S2: =SUM(Q2*P2+R2) -> 808.57 | T2: 47.562941 | V2: 45899
A3: 2 | B3: VÊTEMENTS | C3: WHAT NOT | D3: ♀️ / ♂️ | E3: =IFERROR(__xludf.DUMMYFUNCTION("""COMPUTED_VALUE"""),"Homme/ Femme") -> Homme/ Femme | F3: 45887 | G3: =IFERROR(__xludf.DUMMYFUNCTION("""COMPUTED_VALUE"""),"VWN") -> VWN | H3: A | I3: WHAT NOT | J3: AOÛT | K3: 08 | L3: 45898 | M3: 11 | N3: 38.83 | O3: 7 | P3: 7 | Q3: 5.5471429 | R3: 0 | S3: =SUM(Q3*P3+R3) -> 38.83 | T3: 5.5471429 | V3: 45899
A4: 3 | B4: VÊTEMENTS | C4: PERSO | D4: ♂️/ Benoît | E4: =IFERROR(__xludf.DUMMYFUNCTION("""COMPUTED_VALUE"""),"Homme/ Benoît") -> Homme/ Benoît | F4: 43890 | G4: =IFERROR(__xludf.DUMMYFUNCTION("""COMPUTED_VALUE"""),"VPHB") -> VPHB | H4: A | I4: BENOIT STAMBACH | J4: AOÛT | K4: 08 | L4: 43891 | M4: 1 | N4: 0 | O4: 10 | P4: 10 | Q4: 0 | R4: 0 | S4: =SUM(Q4*P4+R4) -> 0 | T4: 0 | V4: 44075
A5: 4 | B5: JEANS | C5: LEVIS | D5: ♀️/ Kevin | E5: =IFERROR(__xludf.DUMMYFUNCTION("""COMPUTED_VALUE"""),"Femme/ Kevin") -> Femme/ Kevin | F5: 45898 | G5: =IFERROR(__xludf.DUMMYFUNCTION("""COMPUTED_VALUE"""),"JLFK") -> JLFK | H5: A | I5: SUPPLY GDD EXPORT/ 1 | J5: AOÛT | K5: 08 | L5: 45904 | M5: 6 | N5: 408 | O5: 60 | P5: 62 | Q5: 6.5806452 | R5: 30.5 | S5: 438.61 | T5: 7.0743548 | V5: 45905
A6: 5 | B6: VÊTEMENTS | C6: TYMAN | D6: ♂️ | E6: =IFERROR(__xludf.DUMMYFUNCTION("""COMPUTED_VALUE"""),"Homme") -> Homme | F6: 45899 | G6: =IFERROR(__xludf.DUMMYFUNCTION("""COMPUTED_VALUE"""),"VTH") -> VTH | H6: A | I6: TYMAN | J6: SEPTEMBRE | K6: 09 | L6: 45906 | M6: 7 | N6: 41.18 | O6: 29 | P6: 29 | Q6: 1.42 | R6: 0 | S6: =SUM(Q6*P6+R6) -> 41.18 | T6: 1.42 | V6: 45907
A7: 6 | B7: VÊTEMENTS | C7: TYMAN | D7: ♀️ | E7: =IFERROR(__xludf.DUMMYFUNCTION("""COMPUTED_VALUE"""),"Femme") -> Femme | F7: 45899 | G7: =IFERROR(__xludf.DUMMYFUNCTION("""COMPUTED_VALUE"""),"VTF") -> VTF | H7: A | I7: TYMAN | J7: SEPTEMBRE | K7: 09 | L7: 45906 | M7: 7 | N7: 48.28 | O7: 34 | P7: 34 | Q7: 1.42 | R7: 0 | S7: =SUM(Q7*P7+R7) -> 48.28 | T7: 1.42 | V7: 45907
A8: 7 | B8: JACKET | C8: MIX B | D8: ♀️ / ♂️ | E8: =IFERROR(__xludf.DUMMYFUNCTION("""COMPUTED_VALUE"""),"Homme/ Femme") -> Homme/ Femme | F8: 45910 | G8: =IFERROR(__xludf.DUMMYFUNCTION("""COMPUTED_VALUE"""),"JMB") -> JMB | H8: B | I8: SUPPLY GDD EXPORT/ 1 | J8: SEPTEMBRE | K8: 09 | L8: 45922 | M8: 12 | N8: 238 | O8: 60 | P8: 60 | Q8: 3.9666667 | R8: 47 | S8: =SUM(Q8*P8+R8) -> 285 | T8: 4.75 | V8: 45923
A9: 8 | B9: POLAIRE | C9: THE NORTH FACE | D9: ♀️ / ♂️ | E9: =IFERROR(__xludf.DUMMYFUNCTION("""COMPUTED_VALUE"""),"Homme/ Femme") -> Homme/ Femme | F9: 45923 | G9: =IFERROR(__xludf.DUMMYFUNCTION("""COMPUTED_VALUE"""),"PTNF") -> PTNF | H9: A | I9: SUPPLY / 105 | J9: SEPTEMBRE | K9: 09 | L9: 45952 | M9: 29 | N9: 184 | O9: 20 | P9: 20 | Q9: 9.2 | R9: 15.33 | S9: =SUM(Q9*P9+R9) -> 199.33 | T9: 9.9665 | U9: 3652902223 DHL | V9: 45953
A10: 9 | B10: POLAIRE | C10: COLUMBIA | D10: ♀️ / ♂️ | E10: =IFERROR(__xludf.DUMMYFUNCTION("""COMPUTED_VALUE"""),"Homme/ Femme") -> Homme/ Femme | F10: 45923 | G10: =IFERROR(__xludf.DUMMYFUNCTION("""COMPUTED_VALUE"""),"PC") -> PC | H10: A | I10: SUPPLY / 105 | J10: SEPTEMBRE | K10: 09 | L10: 45952 | M10: 29 | N10: 65 | O10: 10 | P10: 10 | Q10: 6.5 | R10: 7.66 | S10: =SUM(Q10*P10+R10) -> 72.66 | T10: 7.266 | U10: 3652902223 DHL | V10: 45953
A11: 10 | B11: JEANS | C11: LEVIS | D11: ♀️ | E11: =IFERROR(__xludf.DUMMYFUNCTION("""COMPUTED_VALUE"""),"Femme") -> Femme | F11: 45925 | G11: =IFERROR(__xludf.DUMMYFUNCTION("""COMPUTED_VALUE"""),"JLF") -> JLF | H11: A | I11: GDD EXPORT / 1 | J11: SEPTEMBRE | K11: 09 | L11: 45937 | M11: 12 | N11: 408 | O11: 60 | P11: 64 | Q11: 6.375 | R11: 45.45 | S11: 453.56 | T11: 7.086875 | V11: 45938
A12: 11 | B12: POLAIRE | C12: THE NORTH FACE | D12: ♀️ / ♂️ | E12: =IFERROR(__xludf.DUMMYFUNCTION("""COMPUTED_VALUE"""),"Homme/ Femme") -> Homme/ Femme | F12: 45925 | G12: =IFERROR(__xludf.DUMMYFUNCTION("""COMPUTED_VALUE"""),"PTNF") -> PTNF | H12: A | I12: GDD EXPORT / 1 | J12: OCTOBRE | K12: 10 | L12: 45937 | M12: 12 | N12: 436 | O12: 40 | P12: 41 | Q12: 10.634146 | R12: 30.05 | S12: =SUM(Q12*P12+R12) -> 466.05 | T12: 11.367073 | V12: 45938
A13: 12 | B13: JEANS | C13: LEVIS | D13: ♀️ | E13: =IFERROR(__xludf.DUMMYFUNCTION("""COMPUTED_VALUE"""),"Femme") -> Femme | F13: 45928 | G13: =IFERROR(__xludf.DUMMYFUNCTION("""COMPUTED_VALUE"""),"JLF") -> JLF | H13: A | I13: SUPPLY GDD EXPORT / 1 | J13: OCTOBRE | K13: 10 | L13: 45937 | M13: 9 | N13: 464 | O13: 70 | P13: 73 | Q13: 6.3561644 | R13: 52.78 | S13: 517 | T13: 7.0821918 | V13: 45938
B14: JACKET | C14: CARHARTT REWORK | D14: ♀️ / ♂️ | E14: =IFERROR(__xludf.DUMMYFUNCTION("""COMPUTED_VALUE"""),"Homme/ Femme") -> Homme/ Femme | F14: 45934 | G14: =IFERROR(__xludf.DUMMYFUNCTION("""COMPUTED_VALUE"""),"JCR") -> JCR | H14: A | I14: SUPPLY CODE 103 | J14: OCTOBRE | K14: 10 | N14: 525 | O14: 30 | S14: =SUM(Q14*P14+R14) -> 0 | V14: FALSE
A15: 14 | B15: PULL | C15: TOMMY | D15: ♀️ | E15: =IFERROR(__xludf.DUMMYFUNCTION("""COMPUTED_VALUE"""),"Femme") -> Femme | F15: 45939 | G15: =IFERROR(__xludf.DUMMYFUNCTION("""COMPUTED_VALUE"""),"PTF") -> PTF | H15: A | I15: SUPPLY CODE 3 | J15: OCTOBRE | K15: 10 | L15: 45944 | M15: 5 | N15: 200 | O15: 55 | P15: 56 | Q15: 3.5714286 | R15: 26 | S15: 226.22 | T15: 4.0396429 | V15: 45945
A16: 15 | B16: JEANS | C16: LEVIS | D16: ♀️ | E16: =IFERROR(__xludf.DUMMYFUNCTION("""COMPUTED_VALUE"""),"Femme") -> Femme | F16: 45941 | G16: =IFERROR(__xludf.DUMMYFUNCTION("""COMPUTED_VALUE"""),"JLF") -> JLF | H16: A | I16: SUPPLY GDD 1 | J16: OCTOBRE | K16: 10 | L16: 45947 | M16: 6 | N16: 654 | O16: 100 | P16: 100 | Q16: 6.54 | R16: 55 | S16: 709.66 | T16: 7.0966 | V16: 45948
A17: 16 | B17: JEANS | C17: LEVIS | D17: ♀️ | E17: =IFERROR(__xludf.DUMMYFUNCTION("""COMPUTED_VALUE"""),"Femme") -> Femme | F17: 45953 | G17: =IFERROR(__xludf.DUMMYFUNCTION("""COMPUTED_VALUE"""),"JLF") -> JLF | H17: A | I17: SUPPLY GDD 1 | L17: 45959 | M17: 6 | N17: 634 | O17: 100 | P17: 100 | Q17: 6.34 | R17: 80.5 | S17: 715.16 | T17: 7.1516 | V17: 45960
B18: PULL | C18: TOMMY | D18: ♀️ | E18: =IFERROR(__xludf.DUMMYFUNCTION("""COMPUTED_VALUE"""),"Femme") -> Femme | F18: 45960 | G18: =IFERROR(__xludf.DUMMYFUNCTION("""COMPUTED_VALUE"""),"PTF") -> PTF | H18: A | I18: SUPPLY CODE 3 | O18: 200 | S18: =SUM(Q18*P18+R18) -> 0 | V18: FALSE
E19: =IFERROR(__xludf.DUMMYFUNCTION("""COMPUTED_VALUE"""),"") | G19: =IFERROR(__xludf.DUMMYFUNCTION("""COMPUTED_VALUE"""),"") | N19: =24*4.75 -> 114 | V19: FALSE

Sheet Stock
A1: ID | B1: ARTICLES | C1: SKU(ancienne nomenclature) | D1: SKU | E1: DATE DE LIVRAISON | F1: DATE DE MISE EN STOCK | G1: MIS EN LIGNE | DATE DE MISE EN LIGNE | H1: PUBLIÉ | DATE DE PUBLICATION | I1: VENDU | DATE DE VENTE | J1: PRIX DE VENTE | K1: TAILLE | L1: LOTS | M1: VALIDER
A2: 3 | B2: VÊTEMENTS PERSO Homme/ Benoît | D2: VPHB-3 | E2: 43891 | F2: 44075
A3: 3 | B3: VÊTEMENTS PERSO Homme/ Benoît | D3: VPHB-4 | E3: 43891 | F3: 44075
A4: 3 | B4: VÊTEMENTS PERSO Homme/ Benoît | D4: VPHB-5 | E4: 43891 | F4: 44075
A5: 3 | B5: VÊTEMENTS PERSO Homme/ Benoît | D5: VPHB-6 | E5: 43891 | F5: 44075
A6: 3 | B6: VÊTEMENTS PERSO Homme/ Benoît | D6: VPHB-7 | E6: 43891 | F6: 44075
A7: 3 | B7: VÊTEMENTS PERSO Homme/ Benoît | D7: VPHB-8 | E7: 43891 | F7: 44075
A8: 3 | B8: VÊTEMENTS PERSO Homme/ Benoît | D8: VPHB-9 | E8: 43891 | F8: 44075
A9: 3 | B9: VÊTEMENTS PERSO Homme/ Benoît | D9: VPHB-10 | E9: 43891 | F9: 44075
A10: 1 | B10: SNEAKERS MIX Homme/ Femme | D10: SM-15 | E10: 45898 | F10: 45899
A11: 1 | B11: SNEAKERS MIX Homme/ Femme | D11: SM-16 | E11: 45898 | F11: 45899
A12: 1 | B12: SNEAKERS MIX Homme/ Femme | D12: SM-17 | E12: 45898 | F12: 45899
A13: 4 | B13: JEANS LEVIS Femme/ Kevin | D13: JLFK-21 | E13: 45904 | F13: 45905
... A374: 16 | B374: JEANS LEVIS Femme | D374: JLF-337 | E374: 45959 | F374: 45960
G375: FALSE | H375: FALSE | I375: FALSE
G376: FALSE | H376: FALSE | I376: FALSE
G377: FALSE | H377: FALSE | I377: FALSE
G378: FALSE | H378: FALSE | I378: FALSE
G379: FALSE | H379: FALSE | I379: FALSE
G380: FALSE | H380: FALSE | I380: FALSE

Sheet Ventes
A1: ID | B1: DATE DE VENTE | C1: ARTICLE | D1: SKU | E1: FRAIS DE COLISSAGE | F1: PRIX VENTE | G1: DÉLAI D'IMMOBILISATION | H1: DELAI DE MISE EN LIGNE | I1: DELAI DE PUBLICATION | J1: DELAI DE VENTE | K1: RETOUR | L1: LOT
A2: 10 | B2: 45973 | C2: JEANS LEVIS Femme | D2: JLF-30 | E2: 0.11 | F2: 16.15 | G2: 13 | H2: 1 | I2: 1 | J2: 11 | K2: FALSE | L2: LOT DE 2
A3: 12 | B3: 45973 | C3: JEANS LEVIS Femme | D3: JLF-93 | E3: 0.11 | F3: 16.15 | G3: 13 | H3: 1 | I3: 1 | J3: 11 | K3: FALSE | L3: LOT DE 2
A4: 12 | B4: 45973 | C4: JEANS LEVIS Femme | D4: JLF-114 | E4: 0.11 | F4: 16 | G4: 13 | H4: 1 | I4: 1 | J4: 11 | K4: FALSE
A5: 14 | B5: 45973 | C5: PULL TOMMY Femme | D5: PTF-3 | E5: 0.073333333 | F5: 8.5 | G5: 28 | H5: 1 | I5: 1 | J5: 26 | K5: FALSE | L5: LOT DE 3
A6: 14 | B6: 45973 | C6: PULL TOMMY Femme | D6: PTF-31 | E6: 0.073333333 | F6: 8.5 | G6: 28 | H6: 1 | I6: 1 | J6: 26 | K6: FALSE | L6: LOT DE 3
A7: 14 | B7: 45973 | C7: PULL TOMMY Femme | D7: PTF-37 | E7: 0.073333333 | F7: 8.5 | G7: 28 | H7: 1 | I7: 1 | J7: 26 | K7: FALSE | L7: LOT DE 3
A8: 15 | B8: 45973 | C8: JEANS LEVIS Femme | D8: JLF-146 | E8: 0.11 | F8: 17 | G8: 13 | H8: 1 | I8: 1 | J8: 11 | K8: FALSE
A9: 15 | B9: 45973 | C9: JEANS LEVIS Femme | D9: JLF-181 | E9: 0.11 | F9: 19 | G9: 13 | H9: 1 | I9: 1 | J9: 11 | K9: FALSE
A10: 15 | B10: 45973 | C10: JEANS LEVIS Femme | D10: JLF-224 | E10: 0.11 | F10: 18 | G10: 13 | H10: 1 | I10: 1 | J10: 11 | K10: FALSE
A11: 15 | B11: 45973 | C11: JEANS LEVIS Femme | D11: JLF-232 | E11: 0.11 | F11: 15 | G11: 13 | H11: 1 | I11: 1 | J11: 11 | K11: FALSE
A12: 15 | B12: 45973 | C12: JEANS LEVIS Femme | D12: JLF-237 | E12: 0.11 | F12: 19 | G12: 13 | H12: 1 | I12: 1 | J12: 11 | K12: FALSE
A13: 15 | B13: 45971 | C13: JEANS LEVIS Femme | D13: JLF-236 | E13: 0.11 | F13: 18 | G13: 11 | H13: 1 | I13: 1 | J13: 9 | K13: FALSE
A14: 12 | B14: 45970 | C14: JEAN LEVIS FEMME | D14: JLF-82 | E14: 0.11 | F14: 17 | G14: 21 | H14: 0 | I14: 0 | J14: 0 | K14: FALSE
A15: 12 | B15: 45970 | C15: JEAN LEVIS FEMME | D15: JLF-118 | E15: 0.11 | F15: 18 | G15: 18 | H15: 0 | I15: 0 | J15: 0 | K15: FALSE
A16: 15 | B16: 45970 | C16: JEAN LEVIS FEMME | D16: JLF-189 | E16: 0.11 | F16: 15 | G16: 5 | H16: 0 | I16: 0 | J16: 0 | K16: FALSE
A17: 15 | B17: 45970 | C17: JEAN LEVIS FEMME | D17: JLF-205 | E17: 0.11 | F17: 14 | G17: 4 | H17: 0 | I17: 0 | J17: 0 | K17: FALSE
A18: 15 | B18: 45970 | C18: JEAN LEVIS FEMME | D18: JLF-210 | E18: 0.11 | F18: 15 | G18: 3 | H18: 0 | I18: 0 | J18: 0 | K18: FALSE
A19: 15 | B19: 45970 | C19: JEAN LEVIS FEMME | D19: JLF-218 | E19: 0.11 | F19: 15 | G19: 2 | H19: 0 | I19: 0 | J19: 0 | K19: FALSE
... A307: 3 | B307: 45901 | C307: VÊTEMENT 15 PERSO | D307: VPHB-1 | E307: 0.11 | F307: 25 | G307: 1 | H307: 0 | I307: 0 | J307: 0 | K307: FALSE

Sheet Compta 09-2025
A1: ID | B1: SKU | C1: LIBELLÉS | D1: DATE DE VENTE | E1: MARGE BRUTE | F1: COEFF MARGE | G1: NBR PCS VENDU
A2: SEMAINE 1 01/09/2025 AU 07/09/2025
A3: 1 | B3: SM-1 | C3: SNEAKERS | D3: 45901 | E3: 7.44 | F3: 1.16 | G3: 1
A4: 3 | B4: VPHB-1 | C4: VÊTEMENT 15 PERSO | D4: 45901 | E4: 25 | G4: 1
A5: 1 | B5: SM-2 | C5: SNEAKERS | D5: 45903 | E5: 42.44 | F5: 1.89 | G5: 1
A6: 1 | B6: SM-3 | C6: SNEAKERS | D6: 45903 | E6: -17.56 | F6: 0.63 | G6: 1
A7: 2 | B7: VWN-1 | C7: VETEMENT WHATNOT | D7: 45903 | E7: -0.55 | F7: 0.9 | G7: 1
A8: 2 | B8: VWN-2 | C8: VETEMENT WHATNOT | D8: 45903 | E8: -0.55 | F8: 0.9 | G8: 1
A9: 2 | B9: VWN-3 | C9: VETEMENT WHATNOT | D9: 45903 | E9: -1.55 | F9: 0.72 | G9: 1
A10: 2 | B10: VWN-4 | C10: VETEMENT WHATNOT | D10: 45903 | E10: 6.45 | F10: 2.16 | G10: 1
A11: 1 | B11: SM-4 | C11: SNEAKERS | D11: 45904 | E11: -7.56 | F11: 0.84 | G11: 1
A12: 2 | B12: VWN-5 | C12: VETEMENT WHATNOT | D12: 45904 | E12: 17.45 | F12: 4.15 | G12: 1
A13: 2 | B13: VWN-6 | C13: VETEMENT WHATNOT | D13: 45905 | E13: 7.45 | F13: 2.34 | G13: 1
A14: 2 | B14: VWN-7 | C14: VETEMENT WHATNOT | D14: 45905 | E14: 12.05 | F14: 3.17 | G14: 1
A15: 1 | B15: SM-5 | C15: SNEAKERS | D15: 45906 | E15: -2.56 | F15: 0.95 | G15: 1
A16: 4 | B16: JLFK-24 | C16: JEANS LEVIS FEMME | D16: 45906 | E16: 15.92 | F16: 3.25 | G16: 1
A17: TOTAL VENTE SEMAINE 1 : 14 | E17: 103.87 | F17: 1.77 | G17: 14
A19: SEMAINE 2 08/09/2025 AU 14/09/2025
A20: 4 | B20: JLFK-23 | C20: JEANS LEVIS FEMME | D20: 45909 | E20: 7.93 | F20: 2.12 | G20: 1
A21: 4 | B21: JLFK-28 | C21: JEANS LEVIS FEMME | D21: 45909 | E21: 8.93 | F21: 2.26 | G21: 1
A22: 4 | B22: JLFK-29 | C22: JEANS LEVIS FEMME | D22: 45909 | E22: 7.93 | F22: 2.12 | G22: 1
A23: 4 | B23: JLFK-25 | C23: JEANS LEVIS FEMME | D23: 45910 | E23: 7.88 | F23: 2.11 | G23: 1
A24: 4 | B24: JLFK-41 | C24: JEANS LEVIS FEMME | D24: 45910 | E24: 7.88 | F24: 2.11 | G24: 1
A25: 4 | B25: JLFK-42 | C25: JEANS LEVIS FEMME | D25: 45910 | E25: 9.93 | F25: 2.4 | G25: 1
A26: 3 | B26: VPHB-2 | C26: VÊTEMENT 17 PERSO | D26: 45911 | E26: 5 | G26: 1
A27: 4 | B27: JLFK-47 | C27: JEANS LEVIS FEMME | D27: 45911 | E27: 10.51 | F27: 2.49 | G27: 1
A28: 4 | B28: JLFK-59 | C28: JEANS LEVIS FEMME | D28: 45911 | E28: 10.51 | F28: 2.49 | G28: 1
A29: 4 | B29: JLFK-67 | C29: JEANS LEVIS FEMME | D29: 45913 | E29: 7.93 | F29: 2.12 | G29: 1
A30: 4 | B30: JLFK-68 | C30: JEANS LEVIS FEMME | D30: 45913 | E30: 4.93 | F30: 1.7 | G30: 1
A31: 1 | B31: SM-6 | C31: SNEAKERS | D31: 45914 | E31: -16.56 | F31: 0.65 | G31: 1
A32: 4 | B32: JLFK-26 | C32: JEANS LEVIS FEMME | D32: 45914 | E32: 6.93 | F32: 1.98 | G32: 1
A33: 4 | B33: JLFK-54 | C33: JEANS LEVIS FEMME | D33: 45914 | E33: 5.93 | F33: 1.84 | G33: 1
A34: 4 | B34: JLFK-57 | C34: JEANS LEVIS FEMME | D34: 45914 | E34: 12.93 | F34: 2.83 | G34: 1
A35: 4 | B35: JLFK-71 | C35: JEANS LEVIS FEMME | D35: 45914 | E35: 6.93 | F35: 1.98 | G35: 1
A36: TOTAL VENTE SEMAINE 2 : 16 | E36: 105.52 | F36: 2.08 | G36: 16
A38: SEMAINE 3 15/09/2025 AU 21/09/2025
A39: 1 | B39: SM-7 | C39: SNEAKERS | D39: 45915 | E39: -2.56 | F39: 0.95 | G39: 1
A40: 1 | B40: SM-8 | C40: SNEAKERS | D40: 45915 | E40: 152.44 | F40: 4.2 | G40: 1
A41: 4 | B41: JLFK-34 | C41: JEANS LEVIS FEMME | D41: 45915 | E41: 6.93 | F41: 1.98 | G41: 1
A42: 4 | B42: JLFK-52 | C42: JEANS LEVIS FEMME | D42: 45915 | E42: 6.93 | F42: 1.98 | G42: 1
...

Sheet Compta 10-2025
A1: ID | B1: SKU | C1: LIBELLÉS | D1: DATE DE VENTE | E1: MARGE BRUTE | F1: COEFF MARGE | G1: NBR PCS VENDU
A2: SEMAINE 1 01/10/2025 AU 05/10/2025
A3: 7 | B3: JMB-99 | C3: JACKET MIX MARQUES GRADE B | D3: 45931 | E3: 20.25 | F3: 5.26 | G3: 1
A4: 7 | B4: JMB-127 | C4: JACKET MIX MARQUES GRADE B | D4: 45932 | E4: 15.25 | F4: 4.21 | G4: 1
A5: 4 | B5: JLFK-35 | C5: JEANS LEVIS FEMME | D5: 45934 | E5: 5.43 | F5: 1.77 | G5: 1
A6: 5 | B6: VTH-7 | C6: VÊTEMENT HOMME TYMAN 7 | D6: 45935 | E6: 4.58 | F6: 4.23 | G6: 1
A7: 7 | B7: JMB-91 | C7: JACKET MIX MARQUES GRADE B | D7: 45935 | E7: 10.25 | F7: 3.16 | G7: 1
A8: 7 | B8: JMB-119 | C8: JACKET MIX MARQUES GRADE B | D8: 45935 | E8: 13.78 | F8: 3.9 | G8: 1
A9: 7 | B9: JMB-126 | C9: JACKET MIX MARQUES GRADE B | D9: 45935 | E9: 15.25 | F9: 4.21 | G9: 1
A10: 7 | B10: JMB-131 | C10: JACKET MIX MARQUES GRADE B | D10: 45935 | E10: 13.78 | F10: 3.9 | G10: 1
A11: 7 | B11: JMB-135 | C11: JACKET MIX MARQUES GRADE B | D11: 45935 | E11: 9.25 | F11: 2.95 | G11: 1
A12: 7 | B12: JMB-136 | C12: JACKET MIX MARQUES GRADE B | D12: 45935 | E12: 14.25 | F12: 4 | G12: 1
A13: TOTAL VENTE SEMAINE 1 : 10 | E13: 122.07 | F13: 3.76 | G13: 10
A15: SEMAINE 2 06/10/2025 AU 12/10/2025
A16: 1 | B16: SM-11 | C16: SNEAKERS | D16: 45937 | E16: -4.76 | F16: 0.9 | G16: 1
A17: 1 | B17: SM-12 | C17: SNEAKERS | D17: 45937 | E17: 31.52 | F17: 1.66 | G17: 1
A18: 4 | B18: JLFK-51 | C18: JEANS LEVIS FEMME | D18: 45937 | E18: 7.93 | F18: 2.12 | G18: 1
A19: 7 | B19: JMB-116 | C19: JACKET MIX MARQUES GRADE B | D19: 45937 | E19: 11.25 | F19: 3.37 | G19: 1
A20: 4 | B20: JLFK-79 | C20: JEANS LEVIS FEMME | D20: 45938 | E20: 12.93 | F20: 2.83 | G20: 1
A21: 4 | B21: JLFK-43 | C21: JEANS LEVIS FEMME | D21: 45939 | E21: 6.93 | F21: 1.98 | G21: 1
A22: 7 | B22: JMB-124 | C22: JACKET MIX MARQUES GRADE B | D22: 45940 | E22: 5.25 | F22: 2.11 | G22: 1
A23: 7 | B23: JMB-111 | C23: JACKET MIX MARQUES GRADE B | D23: 45941 | E23: 11.25 | F23: 3.37 | G23: 1
A24: 10 | B24: JLF-1 | C24: JEAN LEVIS FEMME | D24: 45941 | E24: 14.91 | F24: 3.11 | G24: 1
A25: 10 | B25: JLF-3 | C25: JEAN LEVIS FEMME | D25: 45941 | E25: 13.91 | F25: 2.96 | G25: 1
A26: 10 | B26: JLF-4 | C26: JEAN LEVIS FEMME | D26: 45941 | E26: 12.91 | F26: 2.82 | G26: 1
A27: 10 | B27: JLF-8 | C27: JEAN LEVIS FEMME | D27: 45941 | E27: 11.91 | F27: 2.68 | G27: 1
... A30: 10 | B30: JLF-17 | C30: JEAN LEVIS FEMME | D30: 45942 | E30: 11.91 | F30: 2.68 | G30: 1
A31: TOTAL VENTE SEMAINE 2 : 15 | E31: 167.27 | F31: 2.49 | G31: 15
A33: SEMAINE 3 13/10/2025 AU 19/10/2025
A34: 10 | B34: JLF-2 | C34: JEAN LEVIS FEMME | D34: 45943 | E34: 8.91 | F34: 2.26 | G34: 1
A35: 10 | B35: JLF-18 | C35: JEAN LEVIS FEMME | D35: 45943 | E35: 8.91 | F35: 2.26 | G35: 1
A36: 10 | B36: JLF-22 | C36: JEAN LEVIS FEMME | D36: 45943 | E36: 7.91 | F36: 2.12 | G36: 1
A37: 10 | B37: JLF-27 | C37: JEAN LEVIS FEMME | D37: 45943 | E37: 12.71 | F37: 2.79 | G37: 1
A38: 7 | B38: JMB-87 | C38: JACKET MIX MARQUES GRADE B | D38: 45944 | E38: 9.25 | F38: 2.95 | G38: 1
A39: 1 | B39: SM-13 | C39: SNEAKERS | D39: 45945 | E39: 36.59 | F39: 1.77 | G39: 1
A40: 4 | B40: JLFK-56 | C40: JEANS LEVIS FEMME | D40: 45945 | E40: 3.93 | F40: 1.56 | G40: 1
A41: 10 | B41: JLF-23 | C41: JEAN LEVIS FEMME | D41: 45945 | E41: 9.91 | F41: 2.4 | G41: 1
A42: 10 | B42: JLF-26 | C42: JEAN LEVIS FEMME | D42: 45945 | E42: 12.91 | F42: 2.82 | G42: 1
A43: 7 | B43: JMB-137 | C43: JACKET MIX MARQUES GRADE B | D43: 45946 | E43: 10.25 | F43: 3.16 | G43: 1
A44: 10 | B44: JLF-31 | C44: JEAN LEVIS FEMME | D44: 45946 | E44: 10.51 | F44: 2.48 | G44: 1
...

Sheet Compta 11-2025
A1: ID | B1: SKU | C1: LIBELLÉS | D1: DATE DE VENTE | E1: MARGE BRUTE | F1: COEFF MARGE | G1: NBR PCS VENDU
A2: SEMAINE 1 01/11/2025 AU 02/11/2025
A3: 7 | B3: JMB-81 | C3: JACKET MIX MARQUES GRADE B | D3: 45962 | E3: 5.25 | F3: 2.11 | G3: 1
A4: 10 | B4: JLF-25 | C4: JEAN LEVIS FEMME | D4: 45962 | E4: 8.11 | F4: 2.15 | G4: 1
A5: 12 | B5: JLF-138 | C5: JEAN LEVIS FEMME | D5: 45962 | E5: 10.92 | F5: 2.54 | G5: 1
A6: 15 | B6: JLF-148 | C6: JEAN LEVIS FEMME | D6: 45962 | E6: 10.91 | F6: 2.54 | G6: 1
A7: 15 | B7: JLF-149 | C7: JEAN LEVIS FEMME | D7: 45962 | E7: -2.09 | F7: 0.71 | G7: 1
A8: 15 | B8: JLF-151 | C8: JEAN LEVIS FEMME | D8: 45962 | E8: 6.91 | F8: 1.97 | G8: 1
A9: 14 | B9: PTF-56 | C9: PULL TOMMY FEMME | D9: 45962 | E9: 4.96 | F9: 2.23 | G9: 1
A10: 10 | B10: JLF-14 | C10: JEAN LEVIS FEMME | D10: 45963 | E10: 5.91 | F10: 1.83 | G10: 1
A11: 12 | B11: JLF-94 | C11: JEAN LEVIS FEMME | D11: 45963 | E11: 8.92 | F11: 2.26 | G11: 1
A12: 12 | B12: JLF-101 | C12: JEAN LEVIS FEMME | D12: 45963 | E12: 9.92 | F12: 2.4 | G12: 1
A13: 15 | B13: JLF-144 | C13: JEAN LEVIS FEMME | D13: 45963 | E13: 6.91 | F13: 1.97 | G13: 1
A14: 15 | B14: JLF-147 | C14: JEAN LEVIS FEMME | D14: 45963 | E14: 7.91 | F14: 2.12 | G14: 1
... A18: 15 | B18: JLF-160 | C18: JEAN LEVIS FEMME | D18: 45963 | E18: 11.91 | F18: 2.68 | G18: 1
A19: TOTAL VENTE SEMAINE 1 : 16 | E19: 122.18 | F19: 2.13 | G19: 16
A21: SEMAINE 2 03/11/2025 AU 09/11/2025
A22: 7 | B22: JMB-110 | C22: JACKET MIX MARQUES GRADE B | D22: 45964 | E22: 5.25 | F22: 2.11 | G22: 1
A23: 7 | B23: JMB-134 | C23: JACKET MIX MARQUES GRADE B | D23: 45964 | E23: 14.25 | F23: 4 | G23: 1
A24: 15 | B24: JLF-142 | C24: JEAN LEVIS FEMME | D24: 45964 | E24: 8.11 | F24: 2.14 | G24: 1
A25: 15 | B25: JLF-143 | C25: JEAN LEVIS FEMME | D25: 45964 | E25: 11.91 | F25: 2.68 | G25: 1
A26: 15 | B26: JLF-153 | C26: JEAN LEVIS FEMME | D26: 45964 | E26: 11.91 | F26: 2.68 | G26: 1
A27: 15 | B27: JLF-157 | C27: JEAN LEVIS FEMME | D27: 45964 | E27: 11.91 | F27: 2.68 | G27: 1
A28: 15 | B28: JLF-159 | C28: JEAN LEVIS FEMME | D28: 45964 | E28: 9.16 | F28: 2.29 | G28: 1
A29: 15 | B29: JLF-166 | C29: JEAN LEVIS FEMME | D29: 45964 | E29: 9.16 | F29: 2.29 | G29: 1
A30: 15 | B30: JLF-173 | C30: JEAN LEVIS FEMME | D30: 45964 | E30: 8.11 | F30: 2.14 | G30: 1
A31: 14 | B31: PTF-36 | C31: PULL TOMMY FEMME | D31: 45964 | E31: 7.96 | F31: 2.97 | G31: 1
A32: 14 | B32: PTF-42 | C32: PULL TOMMY FEMME | D32: 45964 | E32: 10.96 | F32: 3.72 | G32: 1
A33: 12 | B33: JLF-89 | C33: JEAN LEVIS FEMME | D33: 45965 | E33: 8.92 | F33: 2.26 | G33: 1
... A74: 14 | B74: PTF-19 | C74: PULL TOMMY FEMME | D74: 45970 | E74: 9.96 | F74: 3.47 | G74: 1
A75: TOTAL VENTE SEMAINE 2 : 53 | E75: 466.31 | F75: 2.42 | G75: 53
A77: SEMAINE 3 10/11/2025 AU 16/11/2025
A78: 15 | B78: JLF-236 | C78: JEANS LEVIS Femme | D78: 45971 | E78: 10.91 | F78: 2.54 | G78: 1
A79: 10 | B79: JLF-30 | C79: JEANS LEVIS Femme | D79: 45973 | E79: 9.06 | F79: 2.28 | G79: 1
A80: 12 | B80: JLF-93 | C80: JEANS LEVIS Femme | D80: 45973 | E80: 9.07 | F80: 2.28 | G80: 1
A81: 12 | B81: JLF-114 | C81: JEANS LEVIS Femme | D81: 45973 | E81: 8.92 | F81: 2.26 | G81: 1
A82: 14 | B82: PTF-3 | C82: PULL TOMMY Femme | D82: 45973 | E82: 4.46 | F82: 2.11 | G82: 1
A83: 14 | B83: PTF-31 | C83: PULL TOMMY Femme | D83: 45973 | E83: 4.46 | F83: 2.11 | G83: 1
A84: 14 | B84: PTF-37 | C84: PULL TOMMY Femme | D84: 45973 | E84: 4.46 | F84: 2.1 | G84: 1
A85: 15 | B85: JLF-146 | C85: JEANS LEVIS Femme | D85: 45973 | E85: 9.91 | F85: 2.4 | G85: 1
...

Sheet Frais
A1: TAILLE DE COLIS | B1: FRAIS DE COLISSAGE | C1: LOT DE 2 | D1: LOT DE 3 | E1: LOT DE 4 | F1: LOT DE 5 | G1: LOT DE 6
A2: PETIT | B2: 0.11
A3: MOYEN | B3: 0.22 | C3: =B3/2 -> 0.11 | D3: =B3/3 -> 0.073333333
A4: GRAND | B4: 0.3 | C4: =B4/2 -> 0.15 | D4: =B4/3 -> 0.1 | E4: =B4/4 -> 0.075 | F4: =B4/5 -> 0.06 | G4: =B4/6 -> 0.05
